2019-06-19 22:41:31,097 [ERROR]  Experienced exception while trying to serve
Traceback (most recent call last):
  File "c:\users\prashant.kamble\appdata\local\programs\python\python36\lib\site-packages\sanic\app.py", line 1096, in run
    serve(**server_settings)
  File "c:\users\prashant.kamble\appdata\local\programs\python\python36\lib\site-packages\sanic\server.py", line 770, in serve
    loop.run_forever()
  File "c:\users\prashant.kamble\appdata\local\programs\python\python36\lib\asyncio\base_events.py", line 438, in run_forever
    self._run_once()
  File "c:\users\prashant.kamble\appdata\local\programs\python\python36\lib\asyncio\base_events.py", line 1415, in _run_once
    event_list = self._selector.select(timeout)
  File "c:\users\prashant.kamble\appdata\local\programs\python\python36\lib\selectors.py", line 323, in select
    r, w, _ = self._select(self._readers, self._writers, [], timeout)
  File "c:\users\prashant.kamble\appdata\local\programs\python\python36\lib\selectors.py", line 314, in _select
    r, w, x = select.select(r, w, w, timeout)
  File "c:\users\prashant.kamble\appdata\local\programs\python\python36\lib\site-packages\engineio\client.py", line 41, in signal_handler
    return original_signal_handler(sig, frame)
KeyboardInterrupt
2019-06-19 22:44:01,471 [ERROR]  Exception occurred in one of response middleware handlers
Traceback (most recent call last):
  File "c:\users\prashant.kamble\appdata\local\programs\python\python36\lib\site-packages\sanic\app.py", line 958, in handle_request
    request, response
  File "c:\users\prashant.kamble\appdata\local\programs\python\python36\lib\site-packages\spf\framework.py", line 543, in _run_response_middleware
    _response = await _response
  File "c:\users\prashant.kamble\appdata\local\programs\python\python36\lib\site-packages\sanic_cors\extension.py", line 266, in unapplied_cors_response_middleware
    set_cors_headers(req, resp, context, res_options)
  File "c:\users\prashant.kamble\appdata\local\programs\python\python36\lib\site-packages\sanic_cors\core.py", line 248, in set_cors_headers
    if resp.headers is None:
AttributeError: 'list' object has no attribute 'headers'
2019-06-19 22:45:38,019 [ERROR]  Exception occurred in one of response middleware handlers
Traceback (most recent call last):
  File "c:\users\prashant.kamble\appdata\local\programs\python\python36\lib\site-packages\sanic\app.py", line 958, in handle_request
    request, response
  File "c:\users\prashant.kamble\appdata\local\programs\python\python36\lib\site-packages\spf\framework.py", line 543, in _run_response_middleware
    _response = await _response
  File "c:\users\prashant.kamble\appdata\local\programs\python\python36\lib\site-packages\sanic_cors\extension.py", line 266, in unapplied_cors_response_middleware
    set_cors_headers(req, resp, context, res_options)
  File "c:\users\prashant.kamble\appdata\local\programs\python\python36\lib\site-packages\sanic_cors\core.py", line 248, in set_cors_headers
    if resp.headers is None:
AttributeError: 'list' object has no attribute 'headers'
2019-06-19 22:46:38,276 [ERROR]  Exception occurred in one of response middleware handlers
Traceback (most recent call last):
  File "c:\users\prashant.kamble\appdata\local\programs\python\python36\lib\site-packages\sanic\app.py", line 958, in handle_request
    request, response
  File "c:\users\prashant.kamble\appdata\local\programs\python\python36\lib\site-packages\spf\framework.py", line 543, in _run_response_middleware
    _response = await _response
  File "c:\users\prashant.kamble\appdata\local\programs\python\python36\lib\site-packages\sanic_cors\extension.py", line 266, in unapplied_cors_response_middleware
    set_cors_headers(req, resp, context, res_options)
  File "c:\users\prashant.kamble\appdata\local\programs\python\python36\lib\site-packages\sanic_cors\core.py", line 248, in set_cors_headers
    if resp.headers is None:
AttributeError: 'list' object has no attribute 'headers'
2019-06-19 22:52:16,840 [ERROR]  Exception occurred in one of response middleware handlers
Traceback (most recent call last):
  File "c:\users\prashant.kamble\appdata\local\programs\python\python36\lib\site-packages\sanic\app.py", line 958, in handle_request
    request, response
  File "c:\users\prashant.kamble\appdata\local\programs\python\python36\lib\site-packages\spf\framework.py", line 543, in _run_response_middleware
    _response = await _response
  File "c:\users\prashant.kamble\appdata\local\programs\python\python36\lib\site-packages\sanic_cors\extension.py", line 266, in unapplied_cors_response_middleware
    set_cors_headers(req, resp, context, res_options)
  File "c:\users\prashant.kamble\appdata\local\programs\python\python36\lib\site-packages\sanic_cors\core.py", line 248, in set_cors_headers
    if resp.headers is None:
AttributeError: 'list' object has no attribute 'headers'
2019-06-20 21:35:47,415 [ERROR]  Exception occurred in one of response middleware handlers
Traceback (most recent call last):
  File "c:\users\prashant.kamble\appdata\local\programs\python\python36\lib\site-packages\sanic\app.py", line 958, in handle_request
    request, response
  File "c:\users\prashant.kamble\appdata\local\programs\python\python36\lib\site-packages\spf\framework.py", line 543, in _run_response_middleware
    _response = await _response
  File "c:\users\prashant.kamble\appdata\local\programs\python\python36\lib\site-packages\sanic_cors\extension.py", line 266, in unapplied_cors_response_middleware
    set_cors_headers(req, resp, context, res_options)
  File "c:\users\prashant.kamble\appdata\local\programs\python\python36\lib\site-packages\sanic_cors\core.py", line 248, in set_cors_headers
    if resp.headers is None:
AttributeError: 'list' object has no attribute 'headers'
2019-06-20 21:37:36,919 [ERROR]  Exception occurred in one of response middleware handlers
Traceback (most recent call last):
  File "c:\users\prashant.kamble\appdata\local\programs\python\python36\lib\site-packages\sanic\app.py", line 958, in handle_request
    request, response
  File "c:\users\prashant.kamble\appdata\local\programs\python\python36\lib\site-packages\spf\framework.py", line 543, in _run_response_middleware
    _response = await _response
  File "c:\users\prashant.kamble\appdata\local\programs\python\python36\lib\site-packages\sanic_cors\extension.py", line 266, in unapplied_cors_response_middleware
    set_cors_headers(req, resp, context, res_options)
  File "c:\users\prashant.kamble\appdata\local\programs\python\python36\lib\site-packages\sanic_cors\core.py", line 248, in set_cors_headers
    if resp.headers is None:
AttributeError: 'list' object has no attribute 'headers'
2019-06-20 21:38:37,891 [ERROR]  Experienced exception while trying to serve
Traceback (most recent call last):
  File "c:\users\prashant.kamble\appdata\local\programs\python\python36\lib\site-packages\sanic\app.py", line 1096, in run
    serve(**server_settings)
  File "c:\users\prashant.kamble\appdata\local\programs\python\python36\lib\site-packages\sanic\server.py", line 770, in serve
    loop.run_forever()
  File "c:\users\prashant.kamble\appdata\local\programs\python\python36\lib\asyncio\base_events.py", line 438, in run_forever
    self._run_once()
  File "c:\users\prashant.kamble\appdata\local\programs\python\python36\lib\asyncio\base_events.py", line 1415, in _run_once
    event_list = self._selector.select(timeout)
  File "c:\users\prashant.kamble\appdata\local\programs\python\python36\lib\selectors.py", line 323, in select
    r, w, _ = self._select(self._readers, self._writers, [], timeout)
  File "c:\users\prashant.kamble\appdata\local\programs\python\python36\lib\selectors.py", line 314, in _select
    r, w, x = select.select(r, w, w, timeout)
  File "c:\users\prashant.kamble\appdata\local\programs\python\python36\lib\site-packages\engineio\client.py", line 41, in signal_handler
    return original_signal_handler(sig, frame)
KeyboardInterrupt
2019-06-20 21:40:37,103 [ERROR]  Exception occurred in one of response middleware handlers
Traceback (most recent call last):
  File "c:\users\prashant.kamble\appdata\local\programs\python\python36\lib\site-packages\sanic\app.py", line 958, in handle_request
    request, response
  File "c:\users\prashant.kamble\appdata\local\programs\python\python36\lib\site-packages\spf\framework.py", line 543, in _run_response_middleware
    _response = await _response
  File "c:\users\prashant.kamble\appdata\local\programs\python\python36\lib\site-packages\sanic_cors\extension.py", line 266, in unapplied_cors_response_middleware
    set_cors_headers(req, resp, context, res_options)
  File "c:\users\prashant.kamble\appdata\local\programs\python\python36\lib\site-packages\sanic_cors\core.py", line 248, in set_cors_headers
    if resp.headers is None:
AttributeError: 'list' object has no attribute 'headers'
2019-06-20 21:41:35,732 [ERROR]  Exception occurred while handling uri: unknown
NoneType: None
2019-06-20 21:42:22,570 [ERROR]  Exception occurred in one of response middleware handlers
Traceback (most recent call last):
  File "c:\users\prashant.kamble\appdata\local\programs\python\python36\lib\site-packages\sanic\app.py", line 958, in handle_request
    request, response
  File "c:\users\prashant.kamble\appdata\local\programs\python\python36\lib\site-packages\spf\framework.py", line 543, in _run_response_middleware
    _response = await _response
  File "c:\users\prashant.kamble\appdata\local\programs\python\python36\lib\site-packages\sanic_cors\extension.py", line 266, in unapplied_cors_response_middleware
    set_cors_headers(req, resp, context, res_options)
  File "c:\users\prashant.kamble\appdata\local\programs\python\python36\lib\site-packages\sanic_cors\core.py", line 248, in set_cors_headers
    if resp.headers is None:
AttributeError: 'list' object has no attribute 'headers'
2019-06-20 21:45:20,089 [ERROR]  Experienced exception while trying to serve
Traceback (most recent call last):
  File "c:\users\prashant.kamble\appdata\local\programs\python\python36\lib\site-packages\sanic\app.py", line 1096, in run
    serve(**server_settings)
  File "c:\users\prashant.kamble\appdata\local\programs\python\python36\lib\site-packages\sanic\server.py", line 770, in serve
    loop.run_forever()
  File "c:\users\prashant.kamble\appdata\local\programs\python\python36\lib\asyncio\base_events.py", line 438, in run_forever
    self._run_once()
  File "c:\users\prashant.kamble\appdata\local\programs\python\python36\lib\asyncio\base_events.py", line 1415, in _run_once
    event_list = self._selector.select(timeout)
  File "c:\users\prashant.kamble\appdata\local\programs\python\python36\lib\selectors.py", line 323, in select
    r, w, _ = self._select(self._readers, self._writers, [], timeout)
  File "c:\users\prashant.kamble\appdata\local\programs\python\python36\lib\selectors.py", line 314, in _select
    r, w, x = select.select(r, w, w, timeout)
  File "c:\users\prashant.kamble\appdata\local\programs\python\python36\lib\site-packages\engineio\client.py", line 41, in signal_handler
    return original_signal_handler(sig, frame)
KeyboardInterrupt
2019-06-20 22:09:10,981 [ERROR]  Exception occurred in one of response middleware handlers
Traceback (most recent call last):
  File "c:\users\prashant.kamble\appdata\local\programs\python\python36\lib\site-packages\sanic\app.py", line 958, in handle_request
    request, response
  File "c:\users\prashant.kamble\appdata\local\programs\python\python36\lib\site-packages\spf\framework.py", line 543, in _run_response_middleware
    _response = await _response
  File "c:\users\prashant.kamble\appdata\local\programs\python\python36\lib\site-packages\sanic_cors\extension.py", line 266, in unapplied_cors_response_middleware
    set_cors_headers(req, resp, context, res_options)
  File "c:\users\prashant.kamble\appdata\local\programs\python\python36\lib\site-packages\sanic_cors\core.py", line 248, in set_cors_headers
    if resp.headers is None:
AttributeError: 'list' object has no attribute 'headers'
2019-06-20 22:09:38,878 [ERROR]  Experienced exception while trying to serve
Traceback (most recent call last):
  File "c:\users\prashant.kamble\appdata\local\programs\python\python36\lib\site-packages\sanic\app.py", line 1096, in run
    serve(**server_settings)
  File "c:\users\prashant.kamble\appdata\local\programs\python\python36\lib\site-packages\sanic\server.py", line 770, in serve
    loop.run_forever()
  File "c:\users\prashant.kamble\appdata\local\programs\python\python36\lib\asyncio\base_events.py", line 438, in run_forever
    self._run_once()
  File "c:\users\prashant.kamble\appdata\local\programs\python\python36\lib\asyncio\base_events.py", line 1415, in _run_once
    event_list = self._selector.select(timeout)
  File "c:\users\prashant.kamble\appdata\local\programs\python\python36\lib\selectors.py", line 323, in select
    r, w, _ = self._select(self._readers, self._writers, [], timeout)
  File "c:\users\prashant.kamble\appdata\local\programs\python\python36\lib\selectors.py", line 314, in _select
    r, w, x = select.select(r, w, w, timeout)
  File "c:\users\prashant.kamble\appdata\local\programs\python\python36\lib\site-packages\engineio\client.py", line 41, in signal_handler
    return original_signal_handler(sig, frame)
KeyboardInterrupt
2019-06-20 22:11:42,691 [ERROR]  Exception occurred while handling uri: 'http://localhost:5005/socket.io/?EIO=3&transport=polling&t=Mjrmz-D'
Traceback (most recent call last):
  File "c:\users\prashant.kamble\appdata\local\programs\python\python36\lib\site-packages\sanic\app.py", line 893, in handle_request
    handler, args, kwargs, uri = self.router.get(request)
  File "c:\users\prashant.kamble\appdata\local\programs\python\python36\lib\site-packages\sanic\router.py", line 407, in get
    return self._get(request.path, request.method, "")
  File "c:\users\prashant.kamble\appdata\local\programs\python\python36\lib\site-packages\sanic\router.py", line 469, in _get
    raise NotFound("Requested URL {} not found".format(url))
sanic.exceptions.NotFound: Requested URL /socket.io/ not found
2019-06-20 22:11:55,938 [ERROR]  Exception occurred while handling uri: 'http://localhost:5005/socket.io/?EIO=3&transport=polling&t=Mjrm_-r'
Traceback (most recent call last):
  File "c:\users\prashant.kamble\appdata\local\programs\python\python36\lib\site-packages\sanic\app.py", line 893, in handle_request
    handler, args, kwargs, uri = self.router.get(request)
  File "c:\users\prashant.kamble\appdata\local\programs\python\python36\lib\site-packages\sanic\router.py", line 407, in get
    return self._get(request.path, request.method, "")
  File "c:\users\prashant.kamble\appdata\local\programs\python\python36\lib\site-packages\sanic\router.py", line 469, in _get
    raise NotFound("Requested URL {} not found".format(url))
sanic.exceptions.NotFound: Requested URL /socket.io/ not found
2019-06-20 22:12:13,404 [ERROR]  Exception occurred while handling uri: 'http://localhost:5005/socket.io/?EIO=3&transport=polling&t=Mjrn3Dl'
Traceback (most recent call last):
  File "c:\users\prashant.kamble\appdata\local\programs\python\python36\lib\site-packages\sanic\app.py", line 893, in handle_request
    handler, args, kwargs, uri = self.router.get(request)
  File "c:\users\prashant.kamble\appdata\local\programs\python\python36\lib\site-packages\sanic\router.py", line 407, in get
    return self._get(request.path, request.method, "")
  File "c:\users\prashant.kamble\appdata\local\programs\python\python36\lib\site-packages\sanic\router.py", line 469, in _get
    raise NotFound("Requested URL {} not found".format(url))
sanic.exceptions.NotFound: Requested URL /socket.io/ not found
2019-06-20 22:12:23,679 [ERROR]  Exception occurred while handling uri: 'http://localhost:5005/socket.io/?EIO=3&transport=polling&t=Mjrn7Ug'
Traceback (most recent call last):
  File "c:\users\prashant.kamble\appdata\local\programs\python\python36\lib\site-packages\sanic\app.py", line 893, in handle_request
    handler, args, kwargs, uri = self.router.get(request)
  File "c:\users\prashant.kamble\appdata\local\programs\python\python36\lib\site-packages\sanic\router.py", line 407, in get
    return self._get(request.path, request.method, "")
  File "c:\users\prashant.kamble\appdata\local\programs\python\python36\lib\site-packages\sanic\router.py", line 469, in _get
    raise NotFound("Requested URL {} not found".format(url))
sanic.exceptions.NotFound: Requested URL /socket.io/ not found
2019-06-20 22:14:04,802 [ERROR]  Exception occurred while handling uri: 'http://localhost:5005/socket.io/?EIO=3&transport=polling&t=Mjrn9_D'
Traceback (most recent call last):
  File "c:\users\prashant.kamble\appdata\local\programs\python\python36\lib\site-packages\sanic\app.py", line 893, in handle_request
    handler, args, kwargs, uri = self.router.get(request)
  File "c:\users\prashant.kamble\appdata\local\programs\python\python36\lib\site-packages\sanic\router.py", line 407, in get
    return self._get(request.path, request.method, "")
  File "c:\users\prashant.kamble\appdata\local\programs\python\python36\lib\site-packages\sanic\router.py", line 469, in _get
    raise NotFound("Requested URL {} not found".format(url))
sanic.exceptions.NotFound: Requested URL /socket.io/ not found
2019-06-20 22:15:26,688 [ERROR]  Exception occurred while handling uri: unknown
NoneType: None
2019-06-20 22:23:56,083 [ERROR]  Experienced exception while trying to serve
Traceback (most recent call last):
  File "c:\users\prashant.kamble\appdata\local\programs\python\python36\lib\site-packages\sanic\app.py", line 1096, in run
    serve(**server_settings)
  File "c:\users\prashant.kamble\appdata\local\programs\python\python36\lib\site-packages\sanic\server.py", line 770, in serve
    loop.run_forever()
  File "c:\users\prashant.kamble\appdata\local\programs\python\python36\lib\asyncio\base_events.py", line 438, in run_forever
    self._run_once()
  File "c:\users\prashant.kamble\appdata\local\programs\python\python36\lib\asyncio\base_events.py", line 1415, in _run_once
    event_list = self._selector.select(timeout)
  File "c:\users\prashant.kamble\appdata\local\programs\python\python36\lib\selectors.py", line 323, in select
    r, w, _ = self._select(self._readers, self._writers, [], timeout)
  File "c:\users\prashant.kamble\appdata\local\programs\python\python36\lib\selectors.py", line 314, in _select
    r, w, x = select.select(r, w, w, timeout)
  File "c:\users\prashant.kamble\appdata\local\programs\python\python36\lib\site-packages\engineio\client.py", line 41, in signal_handler
    return original_signal_handler(sig, frame)
KeyboardInterrupt
2019-06-20 22:24:56,167 [ERROR]  Exception occurred in one of response middleware handlers
Traceback (most recent call last):
  File "c:\users\prashant.kamble\appdata\local\programs\python\python36\lib\site-packages\sanic\app.py", line 958, in handle_request
    request, response
  File "c:\users\prashant.kamble\appdata\local\programs\python\python36\lib\site-packages\spf\framework.py", line 543, in _run_response_middleware
    _response = await _response
  File "c:\users\prashant.kamble\appdata\local\programs\python\python36\lib\site-packages\sanic_cors\extension.py", line 266, in unapplied_cors_response_middleware
    set_cors_headers(req, resp, context, res_options)
  File "c:\users\prashant.kamble\appdata\local\programs\python\python36\lib\site-packages\sanic_cors\core.py", line 248, in set_cors_headers
    if resp.headers is None:
AttributeError: 'list' object has no attribute 'headers'
2019-06-20 22:25:57,215 [ERROR]  Exception occurred while handling uri: unknown
NoneType: None
2019-06-20 22:25:57,310 [ERROR]  Exception occurred while handling uri: unknown
NoneType: None
2019-06-20 22:32:42,085 [ERROR]  Experienced exception while trying to serve
Traceback (most recent call last):
  File "c:\users\prashant.kamble\appdata\local\programs\python\python36\lib\site-packages\sanic\app.py", line 1096, in run
    serve(**server_settings)
  File "c:\users\prashant.kamble\appdata\local\programs\python\python36\lib\site-packages\sanic\server.py", line 770, in serve
    loop.run_forever()
  File "c:\users\prashant.kamble\appdata\local\programs\python\python36\lib\asyncio\base_events.py", line 438, in run_forever
    self._run_once()
  File "c:\users\prashant.kamble\appdata\local\programs\python\python36\lib\asyncio\base_events.py", line 1415, in _run_once
    event_list = self._selector.select(timeout)
  File "c:\users\prashant.kamble\appdata\local\programs\python\python36\lib\selectors.py", line 323, in select
    r, w, _ = self._select(self._readers, self._writers, [], timeout)
  File "c:\users\prashant.kamble\appdata\local\programs\python\python36\lib\selectors.py", line 314, in _select
    r, w, x = select.select(r, w, w, timeout)
  File "c:\users\prashant.kamble\appdata\local\programs\python\python36\lib\site-packages\engineio\client.py", line 41, in signal_handler
    return original_signal_handler(sig, frame)
KeyboardInterrupt
2019-06-20 22:34:03,456 [ERROR]  Exception occurred in one of response middleware handlers
Traceback (most recent call last):
  File "c:\users\prashant.kamble\appdata\local\programs\python\python36\lib\site-packages\sanic\app.py", line 958, in handle_request
    request, response
  File "c:\users\prashant.kamble\appdata\local\programs\python\python36\lib\site-packages\spf\framework.py", line 543, in _run_response_middleware
    _response = await _response
  File "c:\users\prashant.kamble\appdata\local\programs\python\python36\lib\site-packages\sanic_cors\extension.py", line 266, in unapplied_cors_response_middleware
    set_cors_headers(req, resp, context, res_options)
  File "c:\users\prashant.kamble\appdata\local\programs\python\python36\lib\site-packages\sanic_cors\core.py", line 248, in set_cors_headers
    if resp.headers is None:
AttributeError: 'list' object has no attribute 'headers'
2019-06-20 22:35:04,771 [ERROR]  Exception occurred while handling uri: unknown
NoneType: None
2019-06-20 22:35:04,882 [ERROR]  Exception occurred while handling uri: unknown
NoneType: None
2019-06-20 22:35:19,118 [ERROR]  Exception occurred in one of response middleware handlers
Traceback (most recent call last):
  File "c:\users\prashant.kamble\appdata\local\programs\python\python36\lib\site-packages\sanic\app.py", line 958, in handle_request
    request, response
  File "c:\users\prashant.kamble\appdata\local\programs\python\python36\lib\site-packages\spf\framework.py", line 543, in _run_response_middleware
    _response = await _response
  File "c:\users\prashant.kamble\appdata\local\programs\python\python36\lib\site-packages\sanic_cors\extension.py", line 266, in unapplied_cors_response_middleware
    set_cors_headers(req, resp, context, res_options)
  File "c:\users\prashant.kamble\appdata\local\programs\python\python36\lib\site-packages\sanic_cors\core.py", line 248, in set_cors_headers
    if resp.headers is None:
AttributeError: 'list' object has no attribute 'headers'
2019-06-20 22:36:01,348 [ERROR]  Exception occurred in one of response middleware handlers
Traceback (most recent call last):
  File "c:\users\prashant.kamble\appdata\local\programs\python\python36\lib\site-packages\sanic\app.py", line 958, in handle_request
    request, response
  File "c:\users\prashant.kamble\appdata\local\programs\python\python36\lib\site-packages\spf\framework.py", line 543, in _run_response_middleware
    _response = await _response
  File "c:\users\prashant.kamble\appdata\local\programs\python\python36\lib\site-packages\sanic_cors\extension.py", line 266, in unapplied_cors_response_middleware
    set_cors_headers(req, resp, context, res_options)
  File "c:\users\prashant.kamble\appdata\local\programs\python\python36\lib\site-packages\sanic_cors\core.py", line 248, in set_cors_headers
    if resp.headers is None:
AttributeError: 'list' object has no attribute 'headers'
2019-06-29 21:31:28,940 [ERROR]  Exception occurred in one of response middleware handlers
Traceback (most recent call last):
  File "c:\users\prashant.kamble\appdata\local\programs\python\python36\lib\site-packages\sanic\app.py", line 958, in handle_request
    request, response
  File "c:\users\prashant.kamble\appdata\local\programs\python\python36\lib\site-packages\spf\framework.py", line 543, in _run_response_middleware
    _response = await _response
  File "c:\users\prashant.kamble\appdata\local\programs\python\python36\lib\site-packages\sanic_cors\extension.py", line 266, in unapplied_cors_response_middleware
    set_cors_headers(req, resp, context, res_options)
  File "c:\users\prashant.kamble\appdata\local\programs\python\python36\lib\site-packages\sanic_cors\core.py", line 248, in set_cors_headers
    if resp.headers is None:
AttributeError: 'list' object has no attribute 'headers'
2019-06-29 21:34:00,239 [ERROR]  Experienced exception while trying to serve
Traceback (most recent call last):
  File "c:\users\prashant.kamble\appdata\local\programs\python\python36\lib\site-packages\sanic\app.py", line 1096, in run
    serve(**server_settings)
  File "c:\users\prashant.kamble\appdata\local\programs\python\python36\lib\site-packages\sanic\server.py", line 770, in serve
    loop.run_forever()
  File "c:\users\prashant.kamble\appdata\local\programs\python\python36\lib\asyncio\base_events.py", line 438, in run_forever
    self._run_once()
  File "c:\users\prashant.kamble\appdata\local\programs\python\python36\lib\asyncio\base_events.py", line 1415, in _run_once
    event_list = self._selector.select(timeout)
  File "c:\users\prashant.kamble\appdata\local\programs\python\python36\lib\selectors.py", line 323, in select
    r, w, _ = self._select(self._readers, self._writers, [], timeout)
  File "c:\users\prashant.kamble\appdata\local\programs\python\python36\lib\selectors.py", line 314, in _select
    r, w, x = select.select(r, w, w, timeout)
  File "c:\users\prashant.kamble\appdata\local\programs\python\python36\lib\site-packages\engineio\client.py", line 41, in signal_handler
    return original_signal_handler(sig, frame)
KeyboardInterrupt
2019-06-29 21:38:18,979 [ERROR]  Exception occurred in one of response middleware handlers
Traceback (most recent call last):
  File "c:\users\prashant.kamble\appdata\local\programs\python\python36\lib\site-packages\sanic\app.py", line 958, in handle_request
    request, response
  File "c:\users\prashant.kamble\appdata\local\programs\python\python36\lib\site-packages\spf\framework.py", line 543, in _run_response_middleware
    _response = await _response
  File "c:\users\prashant.kamble\appdata\local\programs\python\python36\lib\site-packages\sanic_cors\extension.py", line 266, in unapplied_cors_response_middleware
    set_cors_headers(req, resp, context, res_options)
  File "c:\users\prashant.kamble\appdata\local\programs\python\python36\lib\site-packages\sanic_cors\core.py", line 248, in set_cors_headers
    if resp.headers is None:
AttributeError: 'list' object has no attribute 'headers'
2019-06-29 21:39:16,383 [ERROR]  Exception occurred in one of response middleware handlers
Traceback (most recent call last):
  File "c:\users\prashant.kamble\appdata\local\programs\python\python36\lib\site-packages\sanic\app.py", line 958, in handle_request
    request, response
  File "c:\users\prashant.kamble\appdata\local\programs\python\python36\lib\site-packages\spf\framework.py", line 543, in _run_response_middleware
    _response = await _response
  File "c:\users\prashant.kamble\appdata\local\programs\python\python36\lib\site-packages\sanic_cors\extension.py", line 266, in unapplied_cors_response_middleware
    set_cors_headers(req, resp, context, res_options)
  File "c:\users\prashant.kamble\appdata\local\programs\python\python36\lib\site-packages\sanic_cors\core.py", line 248, in set_cors_headers
    if resp.headers is None:
AttributeError: 'list' object has no attribute 'headers'
2019-06-29 21:49:37,288 [ERROR]  Exception occurred in one of response middleware handlers
Traceback (most recent call last):
  File "c:\users\prashant.kamble\appdata\local\programs\python\python36\lib\site-packages\sanic\app.py", line 958, in handle_request
    request, response
  File "c:\users\prashant.kamble\appdata\local\programs\python\python36\lib\site-packages\spf\framework.py", line 543, in _run_response_middleware
    _response = await _response
  File "c:\users\prashant.kamble\appdata\local\programs\python\python36\lib\site-packages\sanic_cors\extension.py", line 266, in unapplied_cors_response_middleware
    set_cors_headers(req, resp, context, res_options)
  File "c:\users\prashant.kamble\appdata\local\programs\python\python36\lib\site-packages\sanic_cors\core.py", line 248, in set_cors_headers
    if resp.headers is None:
AttributeError: 'list' object has no attribute 'headers'
2019-06-29 21:50:38,353 [ERROR]  Exception occurred while handling uri: unknown
NoneType: None
2019-06-29 21:50:38,456 [ERROR]  Exception occurred while handling uri: unknown
NoneType: None
2019-06-29 21:50:53,184 [ERROR]  Experienced exception while trying to serve
Traceback (most recent call last):
  File "c:\users\prashant.kamble\appdata\local\programs\python\python36\lib\site-packages\sanic\app.py", line 1096, in run
    serve(**server_settings)
  File "c:\users\prashant.kamble\appdata\local\programs\python\python36\lib\site-packages\sanic\server.py", line 770, in serve
    loop.run_forever()
  File "c:\users\prashant.kamble\appdata\local\programs\python\python36\lib\asyncio\base_events.py", line 438, in run_forever
    self._run_once()
  File "c:\users\prashant.kamble\appdata\local\programs\python\python36\lib\asyncio\base_events.py", line 1415, in _run_once
    event_list = self._selector.select(timeout)
  File "c:\users\prashant.kamble\appdata\local\programs\python\python36\lib\selectors.py", line 323, in select
    r, w, _ = self._select(self._readers, self._writers, [], timeout)
  File "c:\users\prashant.kamble\appdata\local\programs\python\python36\lib\selectors.py", line 314, in _select
    r, w, x = select.select(r, w, w, timeout)
  File "c:\users\prashant.kamble\appdata\local\programs\python\python36\lib\site-packages\engineio\client.py", line 41, in signal_handler
    return original_signal_handler(sig, frame)
KeyboardInterrupt
2019-06-29 21:52:26,598 [ERROR]  Exception occurred while handling uri: unknown
NoneType: None
2019-06-29 21:52:26,709 [ERROR]  Exception occurred while handling uri: unknown
NoneType: None
2019-06-29 21:53:02,941 [ERROR]  Exception occurred in one of response middleware handlers
Traceback (most recent call last):
  File "c:\users\prashant.kamble\appdata\local\programs\python\python36\lib\site-packages\sanic\app.py", line 958, in handle_request
    request, response
  File "c:\users\prashant.kamble\appdata\local\programs\python\python36\lib\site-packages\spf\framework.py", line 543, in _run_response_middleware
    _response = await _response
  File "c:\users\prashant.kamble\appdata\local\programs\python\python36\lib\site-packages\sanic_cors\extension.py", line 266, in unapplied_cors_response_middleware
    set_cors_headers(req, resp, context, res_options)
  File "c:\users\prashant.kamble\appdata\local\programs\python\python36\lib\site-packages\sanic_cors\core.py", line 248, in set_cors_headers
    if resp.headers is None:
AttributeError: 'list' object has no attribute 'headers'
2019-06-29 21:54:03,662 [ERROR]  Exception occurred while handling uri: unknown
NoneType: None
2019-06-29 21:54:03,774 [ERROR]  Exception occurred while handling uri: unknown
NoneType: None
2019-06-29 22:36:11,037 [ERROR]  Experienced exception while trying to serve
Traceback (most recent call last):
  File "c:\users\prashant.kamble\appdata\local\programs\python\python36\lib\site-packages\sanic\app.py", line 1096, in run
    serve(**server_settings)
  File "c:\users\prashant.kamble\appdata\local\programs\python\python36\lib\site-packages\sanic\server.py", line 770, in serve
    loop.run_forever()
  File "c:\users\prashant.kamble\appdata\local\programs\python\python36\lib\asyncio\base_events.py", line 438, in run_forever
    self._run_once()
  File "c:\users\prashant.kamble\appdata\local\programs\python\python36\lib\asyncio\base_events.py", line 1415, in _run_once
    event_list = self._selector.select(timeout)
  File "c:\users\prashant.kamble\appdata\local\programs\python\python36\lib\selectors.py", line 323, in select
    r, w, _ = self._select(self._readers, self._writers, [], timeout)
  File "c:\users\prashant.kamble\appdata\local\programs\python\python36\lib\selectors.py", line 314, in _select
    r, w, x = select.select(r, w, w, timeout)
  File "c:\users\prashant.kamble\appdata\local\programs\python\python36\lib\site-packages\engineio\client.py", line 41, in signal_handler
    return original_signal_handler(sig, frame)
KeyboardInterrupt
2019-06-29 22:37:06,913 [ERROR]  Exception occurred in one of response middleware handlers
Traceback (most recent call last):
  File "c:\users\prashant.kamble\appdata\local\programs\python\python36\lib\site-packages\sanic\app.py", line 958, in handle_request
    request, response
  File "c:\users\prashant.kamble\appdata\local\programs\python\python36\lib\site-packages\spf\framework.py", line 543, in _run_response_middleware
    _response = await _response
  File "c:\users\prashant.kamble\appdata\local\programs\python\python36\lib\site-packages\sanic_cors\extension.py", line 266, in unapplied_cors_response_middleware
    set_cors_headers(req, resp, context, res_options)
  File "c:\users\prashant.kamble\appdata\local\programs\python\python36\lib\site-packages\sanic_cors\core.py", line 248, in set_cors_headers
    if resp.headers is None:
AttributeError: 'list' object has no attribute 'headers'
2019-06-29 22:38:32,681 [ERROR]  Exception occurred in one of response middleware handlers
Traceback (most recent call last):
  File "c:\users\prashant.kamble\appdata\local\programs\python\python36\lib\site-packages\sanic\app.py", line 958, in handle_request
    request, response
  File "c:\users\prashant.kamble\appdata\local\programs\python\python36\lib\site-packages\spf\framework.py", line 543, in _run_response_middleware
    _response = await _response
  File "c:\users\prashant.kamble\appdata\local\programs\python\python36\lib\site-packages\sanic_cors\extension.py", line 266, in unapplied_cors_response_middleware
    set_cors_headers(req, resp, context, res_options)
  File "c:\users\prashant.kamble\appdata\local\programs\python\python36\lib\site-packages\sanic_cors\core.py", line 248, in set_cors_headers
    if resp.headers is None:
AttributeError: 'list' object has no attribute 'headers'
2019-06-29 22:39:34,775 [ERROR]  Exception occurred while handling uri: unknown
NoneType: None
2019-06-29 22:39:34,886 [ERROR]  Exception occurred while handling uri: unknown
NoneType: None
2019-06-29 22:40:14,645 [ERROR]  Experienced exception while trying to serve
Traceback (most recent call last):
  File "c:\users\prashant.kamble\appdata\local\programs\python\python36\lib\site-packages\sanic\app.py", line 1096, in run
    serve(**server_settings)
  File "c:\users\prashant.kamble\appdata\local\programs\python\python36\lib\site-packages\sanic\server.py", line 770, in serve
    loop.run_forever()
  File "c:\users\prashant.kamble\appdata\local\programs\python\python36\lib\asyncio\base_events.py", line 438, in run_forever
    self._run_once()
  File "c:\users\prashant.kamble\appdata\local\programs\python\python36\lib\asyncio\base_events.py", line 1415, in _run_once
    event_list = self._selector.select(timeout)
  File "c:\users\prashant.kamble\appdata\local\programs\python\python36\lib\selectors.py", line 323, in select
    r, w, _ = self._select(self._readers, self._writers, [], timeout)
  File "c:\users\prashant.kamble\appdata\local\programs\python\python36\lib\selectors.py", line 314, in _select
    r, w, x = select.select(r, w, w, timeout)
  File "c:\users\prashant.kamble\appdata\local\programs\python\python36\lib\site-packages\engineio\client.py", line 41, in signal_handler
    return original_signal_handler(sig, frame)
KeyboardInterrupt
2019-06-29 22:40:40,369 [ERROR]  Exception occurred in one of response middleware handlers
Traceback (most recent call last):
  File "c:\users\prashant.kamble\appdata\local\programs\python\python36\lib\site-packages\sanic\app.py", line 958, in handle_request
    request, response
  File "c:\users\prashant.kamble\appdata\local\programs\python\python36\lib\site-packages\spf\framework.py", line 543, in _run_response_middleware
    _response = await _response
  File "c:\users\prashant.kamble\appdata\local\programs\python\python36\lib\site-packages\sanic_cors\extension.py", line 266, in unapplied_cors_response_middleware
    set_cors_headers(req, resp, context, res_options)
  File "c:\users\prashant.kamble\appdata\local\programs\python\python36\lib\site-packages\sanic_cors\core.py", line 248, in set_cors_headers
    if resp.headers is None:
AttributeError: 'list' object has no attribute 'headers'
2019-06-29 23:13:15,722 [ERROR]  Exception occurred in one of response middleware handlers
Traceback (most recent call last):
  File "c:\users\prashant.kamble\appdata\local\programs\python\python36\lib\site-packages\sanic\app.py", line 958, in handle_request
    request, response
  File "c:\users\prashant.kamble\appdata\local\programs\python\python36\lib\site-packages\spf\framework.py", line 543, in _run_response_middleware
    _response = await _response
  File "c:\users\prashant.kamble\appdata\local\programs\python\python36\lib\site-packages\sanic_cors\extension.py", line 266, in unapplied_cors_response_middleware
    set_cors_headers(req, resp, context, res_options)
  File "c:\users\prashant.kamble\appdata\local\programs\python\python36\lib\site-packages\sanic_cors\core.py", line 248, in set_cors_headers
    if resp.headers is None:
AttributeError: 'list' object has no attribute 'headers'
2019-06-29 23:15:36,850 [ERROR]  Experienced exception while trying to serve
Traceback (most recent call last):
  File "c:\users\prashant.kamble\appdata\local\programs\python\python36\lib\site-packages\sanic\app.py", line 1096, in run
    serve(**server_settings)
  File "c:\users\prashant.kamble\appdata\local\programs\python\python36\lib\site-packages\sanic\server.py", line 770, in serve
    loop.run_forever()
  File "c:\users\prashant.kamble\appdata\local\programs\python\python36\lib\asyncio\base_events.py", line 438, in run_forever
    self._run_once()
  File "c:\users\prashant.kamble\appdata\local\programs\python\python36\lib\asyncio\base_events.py", line 1415, in _run_once
    event_list = self._selector.select(timeout)
  File "c:\users\prashant.kamble\appdata\local\programs\python\python36\lib\selectors.py", line 323, in select
    r, w, _ = self._select(self._readers, self._writers, [], timeout)
  File "c:\users\prashant.kamble\appdata\local\programs\python\python36\lib\selectors.py", line 314, in _select
    r, w, x = select.select(r, w, w, timeout)
  File "c:\users\prashant.kamble\appdata\local\programs\python\python36\lib\site-packages\engineio\client.py", line 41, in signal_handler
    return original_signal_handler(sig, frame)
KeyboardInterrupt
2019-06-29 23:16:25,403 [ERROR]  Exception occurred in one of response middleware handlers
Traceback (most recent call last):
  File "c:\users\prashant.kamble\appdata\local\programs\python\python36\lib\site-packages\sanic\app.py", line 958, in handle_request
    request, response
  File "c:\users\prashant.kamble\appdata\local\programs\python\python36\lib\site-packages\spf\framework.py", line 543, in _run_response_middleware
    _response = await _response
  File "c:\users\prashant.kamble\appdata\local\programs\python\python36\lib\site-packages\sanic_cors\extension.py", line 266, in unapplied_cors_response_middleware
    set_cors_headers(req, resp, context, res_options)
  File "c:\users\prashant.kamble\appdata\local\programs\python\python36\lib\site-packages\sanic_cors\core.py", line 248, in set_cors_headers
    if resp.headers is None:
AttributeError: 'list' object has no attribute 'headers'
2019-06-29 23:18:30,886 [ERROR]  Experienced exception while trying to serve
Traceback (most recent call last):
  File "c:\users\prashant.kamble\appdata\local\programs\python\python36\lib\site-packages\sanic\app.py", line 1096, in run
    serve(**server_settings)
  File "c:\users\prashant.kamble\appdata\local\programs\python\python36\lib\site-packages\sanic\server.py", line 770, in serve
    loop.run_forever()
  File "c:\users\prashant.kamble\appdata\local\programs\python\python36\lib\asyncio\base_events.py", line 438, in run_forever
    self._run_once()
  File "c:\users\prashant.kamble\appdata\local\programs\python\python36\lib\asyncio\base_events.py", line 1415, in _run_once
    event_list = self._selector.select(timeout)
  File "c:\users\prashant.kamble\appdata\local\programs\python\python36\lib\selectors.py", line 323, in select
    r, w, _ = self._select(self._readers, self._writers, [], timeout)
  File "c:\users\prashant.kamble\appdata\local\programs\python\python36\lib\selectors.py", line 314, in _select
    r, w, x = select.select(r, w, w, timeout)
  File "c:\users\prashant.kamble\appdata\local\programs\python\python36\lib\site-packages\engineio\client.py", line 41, in signal_handler
    return original_signal_handler(sig, frame)
KeyboardInterrupt
2019-06-29 23:18:55,073 [ERROR]  Exception occurred in one of response middleware handlers
Traceback (most recent call last):
  File "c:\users\prashant.kamble\appdata\local\programs\python\python36\lib\site-packages\sanic\app.py", line 958, in handle_request
    request, response
  File "c:\users\prashant.kamble\appdata\local\programs\python\python36\lib\site-packages\spf\framework.py", line 543, in _run_response_middleware
    _response = await _response
  File "c:\users\prashant.kamble\appdata\local\programs\python\python36\lib\site-packages\sanic_cors\extension.py", line 266, in unapplied_cors_response_middleware
    set_cors_headers(req, resp, context, res_options)
  File "c:\users\prashant.kamble\appdata\local\programs\python\python36\lib\site-packages\sanic_cors\core.py", line 248, in set_cors_headers
    if resp.headers is None:
AttributeError: 'list' object has no attribute 'headers'
2019-06-29 23:21:29,014 [ERROR]  Experienced exception while trying to serve
Traceback (most recent call last):
  File "c:\users\prashant.kamble\appdata\local\programs\python\python36\lib\site-packages\sanic\app.py", line 1096, in run
    serve(**server_settings)
  File "c:\users\prashant.kamble\appdata\local\programs\python\python36\lib\site-packages\sanic\server.py", line 770, in serve
    loop.run_forever()
  File "c:\users\prashant.kamble\appdata\local\programs\python\python36\lib\asyncio\base_events.py", line 438, in run_forever
    self._run_once()
  File "c:\users\prashant.kamble\appdata\local\programs\python\python36\lib\asyncio\base_events.py", line 1415, in _run_once
    event_list = self._selector.select(timeout)
  File "c:\users\prashant.kamble\appdata\local\programs\python\python36\lib\selectors.py", line 323, in select
    r, w, _ = self._select(self._readers, self._writers, [], timeout)
  File "c:\users\prashant.kamble\appdata\local\programs\python\python36\lib\selectors.py", line 314, in _select
    r, w, x = select.select(r, w, w, timeout)
  File "c:\users\prashant.kamble\appdata\local\programs\python\python36\lib\site-packages\engineio\client.py", line 41, in signal_handler
    return original_signal_handler(sig, frame)
KeyboardInterrupt
2019-06-29 23:22:29,643 [ERROR]  Exception occurred in one of response middleware handlers
Traceback (most recent call last):
  File "c:\users\prashant.kamble\appdata\local\programs\python\python36\lib\site-packages\sanic\app.py", line 958, in handle_request
    request, response
  File "c:\users\prashant.kamble\appdata\local\programs\python\python36\lib\site-packages\spf\framework.py", line 543, in _run_response_middleware
    _response = await _response
  File "c:\users\prashant.kamble\appdata\local\programs\python\python36\lib\site-packages\sanic_cors\extension.py", line 266, in unapplied_cors_response_middleware
    set_cors_headers(req, resp, context, res_options)
  File "c:\users\prashant.kamble\appdata\local\programs\python\python36\lib\site-packages\sanic_cors\core.py", line 248, in set_cors_headers
    if resp.headers is None:
AttributeError: 'list' object has no attribute 'headers'
2019-06-29 23:22:44,200 [ERROR]  Exception occurred in one of response middleware handlers
Traceback (most recent call last):
  File "c:\users\prashant.kamble\appdata\local\programs\python\python36\lib\site-packages\sanic\app.py", line 958, in handle_request
    request, response
  File "c:\users\prashant.kamble\appdata\local\programs\python\python36\lib\site-packages\spf\framework.py", line 543, in _run_response_middleware
    _response = await _response
  File "c:\users\prashant.kamble\appdata\local\programs\python\python36\lib\site-packages\sanic_cors\extension.py", line 266, in unapplied_cors_response_middleware
    set_cors_headers(req, resp, context, res_options)
  File "c:\users\prashant.kamble\appdata\local\programs\python\python36\lib\site-packages\sanic_cors\core.py", line 248, in set_cors_headers
    if resp.headers is None:
AttributeError: 'list' object has no attribute 'headers'
2019-06-30 13:21:03,236 [ERROR]  Exception occurred in one of response middleware handlers
Traceback (most recent call last):
  File "c:\users\prashant.kamble\appdata\local\programs\python\python36\lib\site-packages\sanic\app.py", line 958, in handle_request
    request, response
  File "c:\users\prashant.kamble\appdata\local\programs\python\python36\lib\site-packages\spf\framework.py", line 543, in _run_response_middleware
    _response = await _response
  File "c:\users\prashant.kamble\appdata\local\programs\python\python36\lib\site-packages\sanic_cors\extension.py", line 266, in unapplied_cors_response_middleware
    set_cors_headers(req, resp, context, res_options)
  File "c:\users\prashant.kamble\appdata\local\programs\python\python36\lib\site-packages\sanic_cors\core.py", line 248, in set_cors_headers
    if resp.headers is None:
AttributeError: 'list' object has no attribute 'headers'
2019-06-30 14:43:39,988 [ERROR]  Exception occurred in one of response middleware handlers
Traceback (most recent call last):
  File "c:\users\prashant.kamble\appdata\local\programs\python\python36\lib\site-packages\sanic\app.py", line 958, in handle_request
    request, response
  File "c:\users\prashant.kamble\appdata\local\programs\python\python36\lib\site-packages\spf\framework.py", line 543, in _run_response_middleware
    _response = await _response
  File "c:\users\prashant.kamble\appdata\local\programs\python\python36\lib\site-packages\sanic_cors\extension.py", line 266, in unapplied_cors_response_middleware
    set_cors_headers(req, resp, context, res_options)
  File "c:\users\prashant.kamble\appdata\local\programs\python\python36\lib\site-packages\sanic_cors\core.py", line 248, in set_cors_headers
    if resp.headers is None:
AttributeError: 'list' object has no attribute 'headers'
2019-06-30 14:44:15,752 [ERROR]  Exception occurred in one of response middleware handlers
Traceback (most recent call last):
  File "c:\users\prashant.kamble\appdata\local\programs\python\python36\lib\site-packages\sanic\app.py", line 958, in handle_request
    request, response
  File "c:\users\prashant.kamble\appdata\local\programs\python\python36\lib\site-packages\spf\framework.py", line 543, in _run_response_middleware
    _response = await _response
  File "c:\users\prashant.kamble\appdata\local\programs\python\python36\lib\site-packages\sanic_cors\extension.py", line 266, in unapplied_cors_response_middleware
    set_cors_headers(req, resp, context, res_options)
  File "c:\users\prashant.kamble\appdata\local\programs\python\python36\lib\site-packages\sanic_cors\core.py", line 248, in set_cors_headers
    if resp.headers is None:
AttributeError: 'list' object has no attribute 'headers'
2019-06-30 16:05:41,842 [ERROR]  Exception occurred in one of response middleware handlers
Traceback (most recent call last):
  File "c:\users\prashant.kamble\appdata\local\programs\python\python36\lib\site-packages\sanic\app.py", line 958, in handle_request
    request, response
  File "c:\users\prashant.kamble\appdata\local\programs\python\python36\lib\site-packages\spf\framework.py", line 543, in _run_response_middleware
    _response = await _response
  File "c:\users\prashant.kamble\appdata\local\programs\python\python36\lib\site-packages\sanic_cors\extension.py", line 266, in unapplied_cors_response_middleware
    set_cors_headers(req, resp, context, res_options)
  File "c:\users\prashant.kamble\appdata\local\programs\python\python36\lib\site-packages\sanic_cors\core.py", line 248, in set_cors_headers
    if resp.headers is None:
AttributeError: 'list' object has no attribute 'headers'
2019-06-30 16:07:10,026 [ERROR]  Exception occurred in one of response middleware handlers
Traceback (most recent call last):
  File "c:\users\prashant.kamble\appdata\local\programs\python\python36\lib\site-packages\sanic\app.py", line 958, in handle_request
    request, response
  File "c:\users\prashant.kamble\appdata\local\programs\python\python36\lib\site-packages\spf\framework.py", line 543, in _run_response_middleware
    _response = await _response
  File "c:\users\prashant.kamble\appdata\local\programs\python\python36\lib\site-packages\sanic_cors\extension.py", line 266, in unapplied_cors_response_middleware
    set_cors_headers(req, resp, context, res_options)
  File "c:\users\prashant.kamble\appdata\local\programs\python\python36\lib\site-packages\sanic_cors\core.py", line 248, in set_cors_headers
    if resp.headers is None:
AttributeError: 'list' object has no attribute 'headers'
2019-06-30 16:08:00,822 [ERROR]  Experienced exception while trying to serve
Traceback (most recent call last):
  File "c:\users\prashant.kamble\appdata\local\programs\python\python36\lib\site-packages\sanic\app.py", line 1096, in run
    serve(**server_settings)
  File "c:\users\prashant.kamble\appdata\local\programs\python\python36\lib\site-packages\sanic\server.py", line 770, in serve
    loop.run_forever()
  File "c:\users\prashant.kamble\appdata\local\programs\python\python36\lib\asyncio\base_events.py", line 438, in run_forever
    self._run_once()
  File "c:\users\prashant.kamble\appdata\local\programs\python\python36\lib\asyncio\base_events.py", line 1415, in _run_once
    event_list = self._selector.select(timeout)
  File "c:\users\prashant.kamble\appdata\local\programs\python\python36\lib\selectors.py", line 323, in select
    r, w, _ = self._select(self._readers, self._writers, [], timeout)
  File "c:\users\prashant.kamble\appdata\local\programs\python\python36\lib\selectors.py", line 314, in _select
    r, w, x = select.select(r, w, w, timeout)
  File "c:\users\prashant.kamble\appdata\local\programs\python\python36\lib\site-packages\engineio\client.py", line 41, in signal_handler
    return original_signal_handler(sig, frame)
KeyboardInterrupt
2019-06-30 16:10:09,388 [ERROR]  Exception occurred in one of response middleware handlers
Traceback (most recent call last):
  File "c:\users\prashant.kamble\appdata\local\programs\python\python36\lib\site-packages\sanic\app.py", line 958, in handle_request
    request, response
  File "c:\users\prashant.kamble\appdata\local\programs\python\python36\lib\site-packages\spf\framework.py", line 543, in _run_response_middleware
    _response = await _response
  File "c:\users\prashant.kamble\appdata\local\programs\python\python36\lib\site-packages\sanic_cors\extension.py", line 266, in unapplied_cors_response_middleware
    set_cors_headers(req, resp, context, res_options)
  File "c:\users\prashant.kamble\appdata\local\programs\python\python36\lib\site-packages\sanic_cors\core.py", line 248, in set_cors_headers
    if resp.headers is None:
AttributeError: 'list' object has no attribute 'headers'
2019-06-30 16:11:10,679 [ERROR]  Exception occurred while handling uri: unknown
NoneType: None
2019-06-30 16:11:10,775 [ERROR]  Exception occurred while handling uri: unknown
NoneType: None
2019-06-30 16:18:14,112 [ERROR]  Exception occurred in one of response middleware handlers
Traceback (most recent call last):
  File "c:\users\prashant.kamble\appdata\local\programs\python\python36\lib\site-packages\sanic\app.py", line 958, in handle_request
    request, response
  File "c:\users\prashant.kamble\appdata\local\programs\python\python36\lib\site-packages\spf\framework.py", line 543, in _run_response_middleware
    _response = await _response
  File "c:\users\prashant.kamble\appdata\local\programs\python\python36\lib\site-packages\sanic_cors\extension.py", line 266, in unapplied_cors_response_middleware
    set_cors_headers(req, resp, context, res_options)
  File "c:\users\prashant.kamble\appdata\local\programs\python\python36\lib\site-packages\sanic_cors\core.py", line 248, in set_cors_headers
    if resp.headers is None:
AttributeError: 'list' object has no attribute 'headers'
2019-06-30 16:22:45,229 [ERROR]  Exception occurred in one of response middleware handlers
Traceback (most recent call last):
  File "c:\users\prashant.kamble\appdata\local\programs\python\python36\lib\site-packages\sanic\app.py", line 958, in handle_request
    request, response
  File "c:\users\prashant.kamble\appdata\local\programs\python\python36\lib\site-packages\spf\framework.py", line 543, in _run_response_middleware
    _response = await _response
  File "c:\users\prashant.kamble\appdata\local\programs\python\python36\lib\site-packages\sanic_cors\extension.py", line 266, in unapplied_cors_response_middleware
    set_cors_headers(req, resp, context, res_options)
  File "c:\users\prashant.kamble\appdata\local\programs\python\python36\lib\site-packages\sanic_cors\core.py", line 248, in set_cors_headers
    if resp.headers is None:
AttributeError: 'list' object has no attribute 'headers'
2019-06-30 16:32:39,998 [ERROR]  Exception occurred in one of response middleware handlers
Traceback (most recent call last):
  File "c:\users\prashant.kamble\appdata\local\programs\python\python36\lib\site-packages\sanic\app.py", line 958, in handle_request
    request, response
  File "c:\users\prashant.kamble\appdata\local\programs\python\python36\lib\site-packages\spf\framework.py", line 543, in _run_response_middleware
    _response = await _response
  File "c:\users\prashant.kamble\appdata\local\programs\python\python36\lib\site-packages\sanic_cors\extension.py", line 266, in unapplied_cors_response_middleware
    set_cors_headers(req, resp, context, res_options)
  File "c:\users\prashant.kamble\appdata\local\programs\python\python36\lib\site-packages\sanic_cors\core.py", line 248, in set_cors_headers
    if resp.headers is None:
AttributeError: 'list' object has no attribute 'headers'
2019-06-30 16:32:40,553 [ERROR]  Exception occurred in one of response middleware handlers
Traceback (most recent call last):
  File "c:\users\prashant.kamble\appdata\local\programs\python\python36\lib\site-packages\sanic\app.py", line 958, in handle_request
    request, response
  File "c:\users\prashant.kamble\appdata\local\programs\python\python36\lib\site-packages\spf\framework.py", line 543, in _run_response_middleware
    _response = await _response
  File "c:\users\prashant.kamble\appdata\local\programs\python\python36\lib\site-packages\sanic_cors\extension.py", line 266, in unapplied_cors_response_middleware
    set_cors_headers(req, resp, context, res_options)
  File "c:\users\prashant.kamble\appdata\local\programs\python\python36\lib\site-packages\sanic_cors\core.py", line 248, in set_cors_headers
    if resp.headers is None:
AttributeError: 'list' object has no attribute 'headers'
2019-06-30 16:37:39,723 [ERROR]  Exception occurred in one of response middleware handlers
Traceback (most recent call last):
  File "c:\users\prashant.kamble\appdata\local\programs\python\python36\lib\site-packages\sanic\app.py", line 958, in handle_request
    request, response
  File "c:\users\prashant.kamble\appdata\local\programs\python\python36\lib\site-packages\spf\framework.py", line 543, in _run_response_middleware
    _response = await _response
  File "c:\users\prashant.kamble\appdata\local\programs\python\python36\lib\site-packages\sanic_cors\extension.py", line 266, in unapplied_cors_response_middleware
    set_cors_headers(req, resp, context, res_options)
  File "c:\users\prashant.kamble\appdata\local\programs\python\python36\lib\site-packages\sanic_cors\core.py", line 248, in set_cors_headers
    if resp.headers is None:
AttributeError: 'list' object has no attribute 'headers'
2019-06-30 16:44:57,446 [ERROR]  Exception occurred in one of response middleware handlers
Traceback (most recent call last):
  File "c:\users\prashant.kamble\appdata\local\programs\python\python36\lib\site-packages\sanic\app.py", line 958, in handle_request
    request, response
  File "c:\users\prashant.kamble\appdata\local\programs\python\python36\lib\site-packages\spf\framework.py", line 543, in _run_response_middleware
    _response = await _response
  File "c:\users\prashant.kamble\appdata\local\programs\python\python36\lib\site-packages\sanic_cors\extension.py", line 266, in unapplied_cors_response_middleware
    set_cors_headers(req, resp, context, res_options)
  File "c:\users\prashant.kamble\appdata\local\programs\python\python36\lib\site-packages\sanic_cors\core.py", line 248, in set_cors_headers
    if resp.headers is None:
AttributeError: 'list' object has no attribute 'headers'
2019-06-30 17:03:04,090 [ERROR]  Exception occurred in one of response middleware handlers
Traceback (most recent call last):
  File "c:\users\prashant.kamble\appdata\local\programs\python\python36\lib\site-packages\sanic\app.py", line 958, in handle_request
    request, response
  File "c:\users\prashant.kamble\appdata\local\programs\python\python36\lib\site-packages\spf\framework.py", line 543, in _run_response_middleware
    _response = await _response
  File "c:\users\prashant.kamble\appdata\local\programs\python\python36\lib\site-packages\sanic_cors\extension.py", line 266, in unapplied_cors_response_middleware
    set_cors_headers(req, resp, context, res_options)
  File "c:\users\prashant.kamble\appdata\local\programs\python\python36\lib\site-packages\sanic_cors\core.py", line 248, in set_cors_headers
    if resp.headers is None:
AttributeError: 'list' object has no attribute 'headers'
2019-07-10 12:43:04,809 [ERROR]  Exception occurred in one of response middleware handlers
Traceback (most recent call last):
  File "c:\users\prashant.kamble\appdata\local\programs\python\python36\lib\site-packages\sanic\app.py", line 958, in handle_request
    request, response
  File "c:\users\prashant.kamble\appdata\local\programs\python\python36\lib\site-packages\spf\framework.py", line 543, in _run_response_middleware
    _response = await _response
  File "c:\users\prashant.kamble\appdata\local\programs\python\python36\lib\site-packages\sanic_cors\extension.py", line 266, in unapplied_cors_response_middleware
    set_cors_headers(req, resp, context, res_options)
  File "c:\users\prashant.kamble\appdata\local\programs\python\python36\lib\site-packages\sanic_cors\core.py", line 248, in set_cors_headers
    if resp.headers is None:
AttributeError: 'list' object has no attribute 'headers'
2019-07-10 15:03:30,515 [ERROR]  Exception occurred while handling uri: 'http://localhost:5005/socket.io/?EIO=3&transport=polling&t=MlREjkj'
Traceback (most recent call last):
  File "c:\users\prashant.kamble\appdata\local\programs\python\python36\lib\site-packages\sanic\app.py", line 893, in handle_request
    handler, args, kwargs, uri = self.router.get(request)
  File "c:\users\prashant.kamble\appdata\local\programs\python\python36\lib\site-packages\sanic\router.py", line 407, in get
    return self._get(request.path, request.method, "")
  File "c:\users\prashant.kamble\appdata\local\programs\python\python36\lib\site-packages\sanic\router.py", line 469, in _get
    raise NotFound("Requested URL {} not found".format(url))
sanic.exceptions.NotFound: Requested URL /socket.io/ not found
2019-07-10 15:03:36,393 [ERROR]  Exception occurred while handling uri: 'http://localhost:5005/socket.io/?EIO=3&transport=polling&t=MlREodG'
Traceback (most recent call last):
  File "c:\users\prashant.kamble\appdata\local\programs\python\python36\lib\site-packages\sanic\app.py", line 893, in handle_request
    handler, args, kwargs, uri = self.router.get(request)
  File "c:\users\prashant.kamble\appdata\local\programs\python\python36\lib\site-packages\sanic\router.py", line 407, in get
    return self._get(request.path, request.method, "")
  File "c:\users\prashant.kamble\appdata\local\programs\python\python36\lib\site-packages\sanic\router.py", line 469, in _get
    raise NotFound("Requested URL {} not found".format(url))
sanic.exceptions.NotFound: Requested URL /socket.io/ not found
2019-07-10 15:03:51,086 [ERROR]  Exception occurred while handling uri: 'http://localhost:5005/socket.io/?EIO=3&transport=polling&t=MlREq4_'
Traceback (most recent call last):
  File "c:\users\prashant.kamble\appdata\local\programs\python\python36\lib\site-packages\sanic\app.py", line 893, in handle_request
    handler, args, kwargs, uri = self.router.get(request)
  File "c:\users\prashant.kamble\appdata\local\programs\python\python36\lib\site-packages\sanic\router.py", line 407, in get
    return self._get(request.path, request.method, "")
  File "c:\users\prashant.kamble\appdata\local\programs\python\python36\lib\site-packages\sanic\router.py", line 469, in _get
    raise NotFound("Requested URL {} not found".format(url))
sanic.exceptions.NotFound: Requested URL /socket.io/ not found
2019-07-10 15:04:02,231 [ERROR]  Exception occurred while handling uri: 'http://localhost:5005/socket.io/?EIO=3&transport=polling&t=MlREtlN'
Traceback (most recent call last):
  File "c:\users\prashant.kamble\appdata\local\programs\python\python36\lib\site-packages\sanic\app.py", line 893, in handle_request
    handler, args, kwargs, uri = self.router.get(request)
  File "c:\users\prashant.kamble\appdata\local\programs\python\python36\lib\site-packages\sanic\router.py", line 407, in get
    return self._get(request.path, request.method, "")
  File "c:\users\prashant.kamble\appdata\local\programs\python\python36\lib\site-packages\sanic\router.py", line 469, in _get
    raise NotFound("Requested URL {} not found".format(url))
sanic.exceptions.NotFound: Requested URL /socket.io/ not found
2019-07-10 15:04:10,950 [ERROR]  Exception occurred while handling uri: 'http://localhost:5005/socket.io/?EIO=3&transport=polling&t=MlREwRG'
Traceback (most recent call last):
  File "c:\users\prashant.kamble\appdata\local\programs\python\python36\lib\site-packages\sanic\app.py", line 893, in handle_request
    handler, args, kwargs, uri = self.router.get(request)
  File "c:\users\prashant.kamble\appdata\local\programs\python\python36\lib\site-packages\sanic\router.py", line 407, in get
    return self._get(request.path, request.method, "")
  File "c:\users\prashant.kamble\appdata\local\programs\python\python36\lib\site-packages\sanic\router.py", line 469, in _get
    raise NotFound("Requested URL {} not found".format(url))
sanic.exceptions.NotFound: Requested URL /socket.io/ not found
2019-07-10 15:05:44,757 [ERROR]  Exception occurred while handling uri: 'http://localhost:5005/socket.io/?EIO=3&transport=polling&t=MlRF2ke'
Traceback (most recent call last):
  File "c:\users\prashant.kamble\appdata\local\programs\python\python36\lib\site-packages\sanic\app.py", line 893, in handle_request
    handler, args, kwargs, uri = self.router.get(request)
  File "c:\users\prashant.kamble\appdata\local\programs\python\python36\lib\site-packages\sanic\router.py", line 407, in get
    return self._get(request.path, request.method, "")
  File "c:\users\prashant.kamble\appdata\local\programs\python\python36\lib\site-packages\sanic\router.py", line 469, in _get
    raise NotFound("Requested URL {} not found".format(url))
sanic.exceptions.NotFound: Requested URL /socket.io/ not found
2019-07-10 15:05:44,759 [ERROR]  Exception occurred while handling uri: 'http://localhost:5005/socket.io/?EIO=3&transport=polling&t=MlRF9KM'
Traceback (most recent call last):
  File "c:\users\prashant.kamble\appdata\local\programs\python\python36\lib\site-packages\sanic\app.py", line 893, in handle_request
    handler, args, kwargs, uri = self.router.get(request)
  File "c:\users\prashant.kamble\appdata\local\programs\python\python36\lib\site-packages\sanic\router.py", line 407, in get
    return self._get(request.path, request.method, "")
  File "c:\users\prashant.kamble\appdata\local\programs\python\python36\lib\site-packages\sanic\router.py", line 469, in _get
    raise NotFound("Requested URL {} not found".format(url))
sanic.exceptions.NotFound: Requested URL /socket.io/ not found
2019-07-10 15:05:44,761 [ERROR]  Exception occurred while handling uri: 'http://localhost:5005/socket.io/?EIO=3&transport=polling&t=MlRFFwD'
Traceback (most recent call last):
  File "c:\users\prashant.kamble\appdata\local\programs\python\python36\lib\site-packages\sanic\app.py", line 893, in handle_request
    handler, args, kwargs, uri = self.router.get(request)
  File "c:\users\prashant.kamble\appdata\local\programs\python\python36\lib\site-packages\sanic\router.py", line 407, in get
    return self._get(request.path, request.method, "")
  File "c:\users\prashant.kamble\appdata\local\programs\python\python36\lib\site-packages\sanic\router.py", line 469, in _get
    raise NotFound("Requested URL {} not found".format(url))
sanic.exceptions.NotFound: Requested URL /socket.io/ not found
2019-07-10 15:05:44,763 [ERROR]  Exception occurred while handling uri: 'http://localhost:5005/socket.io/?EIO=3&transport=polling&t=MlREyOG'
Traceback (most recent call last):
  File "c:\users\prashant.kamble\appdata\local\programs\python\python36\lib\site-packages\sanic\app.py", line 893, in handle_request
    handler, args, kwargs, uri = self.router.get(request)
  File "c:\users\prashant.kamble\appdata\local\programs\python\python36\lib\site-packages\sanic\router.py", line 407, in get
    return self._get(request.path, request.method, "")
  File "c:\users\prashant.kamble\appdata\local\programs\python\python36\lib\site-packages\sanic\router.py", line 469, in _get
    raise NotFound("Requested URL {} not found".format(url))
sanic.exceptions.NotFound: Requested URL /socket.io/ not found
2019-07-10 15:06:00,248 [ERROR]  Exception occurred while handling uri: 'http://localhost:5005/socket.io/?EIO=3&transport=polling&t=MlRFJK_'
Traceback (most recent call last):
  File "c:\users\prashant.kamble\appdata\local\programs\python\python36\lib\site-packages\sanic\app.py", line 893, in handle_request
    handler, args, kwargs, uri = self.router.get(request)
  File "c:\users\prashant.kamble\appdata\local\programs\python\python36\lib\site-packages\sanic\router.py", line 407, in get
    return self._get(request.path, request.method, "")
  File "c:\users\prashant.kamble\appdata\local\programs\python\python36\lib\site-packages\sanic\router.py", line 469, in _get
    raise NotFound("Requested URL {} not found".format(url))
sanic.exceptions.NotFound: Requested URL /socket.io/ not found
2019-07-10 15:06:13,079 [ERROR]  Exception occurred while handling uri: 'http://localhost:5005/socket.io/?EIO=3&transport=polling&t=MlRFNUd'
Traceback (most recent call last):
  File "c:\users\prashant.kamble\appdata\local\programs\python\python36\lib\site-packages\sanic\app.py", line 893, in handle_request
    handler, args, kwargs, uri = self.router.get(request)
  File "c:\users\prashant.kamble\appdata\local\programs\python\python36\lib\site-packages\sanic\router.py", line 407, in get
    return self._get(request.path, request.method, "")
  File "c:\users\prashant.kamble\appdata\local\programs\python\python36\lib\site-packages\sanic\router.py", line 469, in _get
    raise NotFound("Requested URL {} not found".format(url))
sanic.exceptions.NotFound: Requested URL /socket.io/ not found
2019-07-10 15:06:25,723 [ERROR]  Exception occurred while handling uri: 'http://localhost:5005/socket.io/?EIO=3&transport=polling&t=MlRFQg3'
Traceback (most recent call last):
  File "c:\users\prashant.kamble\appdata\local\programs\python\python36\lib\site-packages\sanic\app.py", line 893, in handle_request
    handler, args, kwargs, uri = self.router.get(request)
  File "c:\users\prashant.kamble\appdata\local\programs\python\python36\lib\site-packages\sanic\router.py", line 407, in get
    return self._get(request.path, request.method, "")
  File "c:\users\prashant.kamble\appdata\local\programs\python\python36\lib\site-packages\sanic\router.py", line 469, in _get
    raise NotFound("Requested URL {} not found".format(url))
sanic.exceptions.NotFound: Requested URL /socket.io/ not found
2019-07-11 12:27:27,585 [ERROR]  Exception occurred while handling uri: 'http://localhost:5005/socket.io/?EIO=3&transport=polling&t=MlVqf2j'
Traceback (most recent call last):
  File "c:\users\prashant.kamble\appdata\local\programs\python\python36\lib\site-packages\sanic\app.py", line 893, in handle_request
    handler, args, kwargs, uri = self.router.get(request)
  File "c:\users\prashant.kamble\appdata\local\programs\python\python36\lib\site-packages\sanic\router.py", line 407, in get
    return self._get(request.path, request.method, "")
  File "c:\users\prashant.kamble\appdata\local\programs\python\python36\lib\site-packages\sanic\router.py", line 469, in _get
    raise NotFound("Requested URL {} not found".format(url))
sanic.exceptions.NotFound: Requested URL /socket.io/ not found
2019-07-11 12:27:32,935 [ERROR]  Exception occurred while handling uri: 'http://localhost:5005/socket.io/?EIO=3&transport=polling&t=MlVqgNH'
Traceback (most recent call last):
  File "c:\users\prashant.kamble\appdata\local\programs\python\python36\lib\site-packages\sanic\app.py", line 893, in handle_request
    handler, args, kwargs, uri = self.router.get(request)
  File "c:\users\prashant.kamble\appdata\local\programs\python\python36\lib\site-packages\sanic\router.py", line 407, in get
    return self._get(request.path, request.method, "")
  File "c:\users\prashant.kamble\appdata\local\programs\python\python36\lib\site-packages\sanic\router.py", line 469, in _get
    raise NotFound("Requested URL {} not found".format(url))
sanic.exceptions.NotFound: Requested URL /socket.io/ not found
2019-07-11 12:27:45,363 [ERROR]  Exception occurred while handling uri: 'http://localhost:5005/socket.io/?EIO=3&transport=polling&t=MlVqhgO'
Traceback (most recent call last):
  File "c:\users\prashant.kamble\appdata\local\programs\python\python36\lib\site-packages\sanic\app.py", line 893, in handle_request
    handler, args, kwargs, uri = self.router.get(request)
  File "c:\users\prashant.kamble\appdata\local\programs\python\python36\lib\site-packages\sanic\router.py", line 407, in get
    return self._get(request.path, request.method, "")
  File "c:\users\prashant.kamble\appdata\local\programs\python\python36\lib\site-packages\sanic\router.py", line 469, in _get
    raise NotFound("Requested URL {} not found".format(url))
sanic.exceptions.NotFound: Requested URL /socket.io/ not found
2019-07-11 12:27:50,678 [ERROR]  Exception occurred while handling uri: 'http://localhost:5005/socket.io/?EIO=3&transport=polling&t=MlVqkiX'
Traceback (most recent call last):
  File "c:\users\prashant.kamble\appdata\local\programs\python\python36\lib\site-packages\sanic\app.py", line 893, in handle_request
    handler, args, kwargs, uri = self.router.get(request)
  File "c:\users\prashant.kamble\appdata\local\programs\python\python36\lib\site-packages\sanic\router.py", line 407, in get
    return self._get(request.path, request.method, "")
  File "c:\users\prashant.kamble\appdata\local\programs\python\python36\lib\site-packages\sanic\router.py", line 469, in _get
    raise NotFound("Requested URL {} not found".format(url))
sanic.exceptions.NotFound: Requested URL /socket.io/ not found
2019-07-11 12:27:56,761 [ERROR]  Exception occurred while handling uri: 'http://localhost:5005/socket.io/?EIO=3&transport=polling&t=MlVql_g'
Traceback (most recent call last):
  File "c:\users\prashant.kamble\appdata\local\programs\python\python36\lib\site-packages\sanic\app.py", line 893, in handle_request
    handler, args, kwargs, uri = self.router.get(request)
  File "c:\users\prashant.kamble\appdata\local\programs\python\python36\lib\site-packages\sanic\router.py", line 407, in get
    return self._get(request.path, request.method, "")
  File "c:\users\prashant.kamble\appdata\local\programs\python\python36\lib\site-packages\sanic\router.py", line 469, in _get
    raise NotFound("Requested URL {} not found".format(url))
sanic.exceptions.NotFound: Requested URL /socket.io/ not found
2019-07-11 12:28:04,690 [ERROR]  Exception occurred while handling uri: 'http://localhost:5005/socket.io/?EIO=3&transport=polling&t=MlVqnUd'
Traceback (most recent call last):
  File "c:\users\prashant.kamble\appdata\local\programs\python\python36\lib\site-packages\sanic\app.py", line 893, in handle_request
    handler, args, kwargs, uri = self.router.get(request)
  File "c:\users\prashant.kamble\appdata\local\programs\python\python36\lib\site-packages\sanic\router.py", line 407, in get
    return self._get(request.path, request.method, "")
  File "c:\users\prashant.kamble\appdata\local\programs\python\python36\lib\site-packages\sanic\router.py", line 469, in _get
    raise NotFound("Requested URL {} not found".format(url))
sanic.exceptions.NotFound: Requested URL /socket.io/ not found
2019-07-11 12:29:55,422 [ERROR]  Exception occurred while handling uri: unknown
NoneType: None
2019-07-11 12:29:55,424 [ERROR]  Exception occurred while handling uri: 'http://localhost:5005/socket.io/?EIO=3&transport=polling&t=MlVqpQW'
Traceback (most recent call last):
  File "c:\users\prashant.kamble\appdata\local\programs\python\python36\lib\site-packages\sanic\app.py", line 893, in handle_request
    handler, args, kwargs, uri = self.router.get(request)
  File "c:\users\prashant.kamble\appdata\local\programs\python\python36\lib\site-packages\sanic\router.py", line 407, in get
    return self._get(request.path, request.method, "")
  File "c:\users\prashant.kamble\appdata\local\programs\python\python36\lib\site-packages\sanic\router.py", line 469, in _get
    raise NotFound("Requested URL {} not found".format(url))
sanic.exceptions.NotFound: Requested URL /socket.io/ not found
2019-07-11 12:40:02,141 [ERROR]  Unable to start server
Traceback (most recent call last):
  File "C:\Users\Prashant.Kamble\AppData\Local\Programs\Python\Python36\Lib\asyncio\base_events.py", line 1062, in create_server
    sock.bind(sa)
OSError: [WinError 10048] Only one usage of each socket address (protocol/network address/port) is normally permitted

During handling of the above exception, another exception occurred:

Traceback (most recent call last):
  File "c:\users\prashant.kamble\appdata\local\programs\python\python36\lib\site-packages\sanic\server.py", line 745, in serve
    http_server = loop.run_until_complete(server_coroutine)
  File "C:\Users\Prashant.Kamble\AppData\Local\Programs\Python\Python36\Lib\asyncio\base_events.py", line 484, in run_until_complete
    return future.result()
  File "C:\Users\Prashant.Kamble\AppData\Local\Programs\Python\Python36\Lib\asyncio\base_events.py", line 1066, in create_server
    % (sa, err.strerror.lower()))
OSError: [Errno 10048] error while attempting to bind on address ('0.0.0.0', 5005): only one usage of each socket address (protocol/network address/port) is normally permitted
2019-07-11 12:40:44,960 [ERROR]  Exception occurred while handling uri: 'http://localhost:5005/socket.io/?EIO=3&transport=polling&t=MlVthki'
Traceback (most recent call last):
  File "c:\users\prashant.kamble\appdata\local\programs\python\python36\lib\site-packages\sanic\app.py", line 893, in handle_request
    handler, args, kwargs, uri = self.router.get(request)
  File "c:\users\prashant.kamble\appdata\local\programs\python\python36\lib\site-packages\sanic\router.py", line 407, in get
    return self._get(request.path, request.method, "")
  File "c:\users\prashant.kamble\appdata\local\programs\python\python36\lib\site-packages\sanic\router.py", line 469, in _get
    raise NotFound("Requested URL {} not found".format(url))
sanic.exceptions.NotFound: Requested URL /socket.io/ not found
2019-07-11 12:40:52,593 [ERROR]  Exception occurred while handling uri: 'http://localhost:5005/socket.io/?EIO=3&transport=polling&t=MlVtj1m'
Traceback (most recent call last):
  File "c:\users\prashant.kamble\appdata\local\programs\python\python36\lib\site-packages\sanic\app.py", line 893, in handle_request
    handler, args, kwargs, uri = self.router.get(request)
  File "c:\users\prashant.kamble\appdata\local\programs\python\python36\lib\site-packages\sanic\router.py", line 407, in get
    return self._get(request.path, request.method, "")
  File "c:\users\prashant.kamble\appdata\local\programs\python\python36\lib\site-packages\sanic\router.py", line 469, in _get
    raise NotFound("Requested URL {} not found".format(url))
sanic.exceptions.NotFound: Requested URL /socket.io/ not found
2019-07-11 12:41:05,692 [ERROR]  Exception occurred while handling uri: 'http://localhost:5005/socket.io/?EIO=3&transport=polling&t=MlVtkv2'
Traceback (most recent call last):
  File "c:\users\prashant.kamble\appdata\local\programs\python\python36\lib\site-packages\sanic\app.py", line 893, in handle_request
    handler, args, kwargs, uri = self.router.get(request)
  File "c:\users\prashant.kamble\appdata\local\programs\python\python36\lib\site-packages\sanic\router.py", line 407, in get
    return self._get(request.path, request.method, "")
  File "c:\users\prashant.kamble\appdata\local\programs\python\python36\lib\site-packages\sanic\router.py", line 469, in _get
    raise NotFound("Requested URL {} not found".format(url))
sanic.exceptions.NotFound: Requested URL /socket.io/ not found
2019-07-11 12:42:02,969 [ERROR]  Exception occurred while handling uri: 'http://localhost:5005/socket.io/?EIO=3&transport=polling&t=MlVto5j'
Traceback (most recent call last):
  File "c:\users\prashant.kamble\appdata\local\programs\python\python36\lib\site-packages\sanic\app.py", line 893, in handle_request
    handler, args, kwargs, uri = self.router.get(request)
  File "c:\users\prashant.kamble\appdata\local\programs\python\python36\lib\site-packages\sanic\router.py", line 407, in get
    return self._get(request.path, request.method, "")
  File "c:\users\prashant.kamble\appdata\local\programs\python\python36\lib\site-packages\sanic\router.py", line 469, in _get
    raise NotFound("Requested URL {} not found".format(url))
sanic.exceptions.NotFound: Requested URL /socket.io/ not found
2019-07-11 12:42:30,283 [ERROR]  Exception occurred while handling uri: 'http://localhost:5005/socket.io/?EIO=3&transport=polling&t=MlVu5DU'
Traceback (most recent call last):
  File "c:\users\prashant.kamble\appdata\local\programs\python\python36\lib\site-packages\sanic\app.py", line 893, in handle_request
    handler, args, kwargs, uri = self.router.get(request)
  File "c:\users\prashant.kamble\appdata\local\programs\python\python36\lib\site-packages\sanic\router.py", line 407, in get
    return self._get(request.path, request.method, "")
  File "c:\users\prashant.kamble\appdata\local\programs\python\python36\lib\site-packages\sanic\router.py", line 469, in _get
    raise NotFound("Requested URL {} not found".format(url))
sanic.exceptions.NotFound: Requested URL /socket.io/ not found
2019-07-11 12:42:39,723 [ERROR]  Exception occurred while handling uri: 'http://localhost:5005/socket.io/?EIO=3&transport=polling&t=MlVu6lR'
Traceback (most recent call last):
  File "c:\users\prashant.kamble\appdata\local\programs\python\python36\lib\site-packages\sanic\app.py", line 893, in handle_request
    handler, args, kwargs, uri = self.router.get(request)
  File "c:\users\prashant.kamble\appdata\local\programs\python\python36\lib\site-packages\sanic\router.py", line 407, in get
    return self._get(request.path, request.method, "")
  File "c:\users\prashant.kamble\appdata\local\programs\python\python36\lib\site-packages\sanic\router.py", line 469, in _get
    raise NotFound("Requested URL {} not found".format(url))
sanic.exceptions.NotFound: Requested URL /socket.io/ not found
2019-07-11 12:44:18,197 [ERROR]  Exception occurred while handling uri: 'http://localhost:5005/socket.io/?EIO=3&transport=polling&t=MlVuTTf'
Traceback (most recent call last):
  File "c:\users\prashant.kamble\appdata\local\programs\python\python36\lib\site-packages\sanic\app.py", line 893, in handle_request
    handler, args, kwargs, uri = self.router.get(request)
  File "c:\users\prashant.kamble\appdata\local\programs\python\python36\lib\site-packages\sanic\router.py", line 407, in get
    return self._get(request.path, request.method, "")
  File "c:\users\prashant.kamble\appdata\local\programs\python\python36\lib\site-packages\sanic\router.py", line 469, in _get
    raise NotFound("Requested URL {} not found".format(url))
sanic.exceptions.NotFound: Requested URL /socket.io/ not found
2019-07-11 12:44:24,586 [ERROR]  Exception occurred while handling uri: 'http://localhost:5005/socket.io/?EIO=3&transport=polling&t=MlVuX5b'
Traceback (most recent call last):
  File "c:\users\prashant.kamble\appdata\local\programs\python\python36\lib\site-packages\sanic\app.py", line 893, in handle_request
    handler, args, kwargs, uri = self.router.get(request)
  File "c:\users\prashant.kamble\appdata\local\programs\python\python36\lib\site-packages\sanic\router.py", line 407, in get
    return self._get(request.path, request.method, "")
  File "c:\users\prashant.kamble\appdata\local\programs\python\python36\lib\site-packages\sanic\router.py", line 469, in _get
    raise NotFound("Requested URL {} not found".format(url))
sanic.exceptions.NotFound: Requested URL /socket.io/ not found
2019-07-11 12:44:31,327 [ERROR]  Exception occurred while handling uri: 'http://localhost:5005/socket.io/?EIO=3&transport=polling&t=MlVuYfP'
Traceback (most recent call last):
  File "c:\users\prashant.kamble\appdata\local\programs\python\python36\lib\site-packages\sanic\app.py", line 893, in handle_request
    handler, args, kwargs, uri = self.router.get(request)
  File "c:\users\prashant.kamble\appdata\local\programs\python\python36\lib\site-packages\sanic\router.py", line 407, in get
    return self._get(request.path, request.method, "")
  File "c:\users\prashant.kamble\appdata\local\programs\python\python36\lib\site-packages\sanic\router.py", line 469, in _get
    raise NotFound("Requested URL {} not found".format(url))
sanic.exceptions.NotFound: Requested URL /socket.io/ not found
2019-07-11 12:44:40,874 [ERROR]  Exception occurred while handling uri: 'http://localhost:5005/socket.io/?EIO=3&transport=polling&t=MlVuaIi'
Traceback (most recent call last):
  File "c:\users\prashant.kamble\appdata\local\programs\python\python36\lib\site-packages\sanic\app.py", line 893, in handle_request
    handler, args, kwargs, uri = self.router.get(request)
  File "c:\users\prashant.kamble\appdata\local\programs\python\python36\lib\site-packages\sanic\router.py", line 407, in get
    return self._get(request.path, request.method, "")
  File "c:\users\prashant.kamble\appdata\local\programs\python\python36\lib\site-packages\sanic\router.py", line 469, in _get
    raise NotFound("Requested URL {} not found".format(url))
sanic.exceptions.NotFound: Requested URL /socket.io/ not found
2019-07-11 12:45:02,762 [ERROR]  Exception occurred while handling uri: 'http://localhost:5005/socket.io/?EIO=3&transport=polling&t=MlVucdv'
Traceback (most recent call last):
  File "c:\users\prashant.kamble\appdata\local\programs\python\python36\lib\site-packages\sanic\app.py", line 893, in handle_request
    handler, args, kwargs, uri = self.router.get(request)
  File "c:\users\prashant.kamble\appdata\local\programs\python\python36\lib\site-packages\sanic\router.py", line 407, in get
    return self._get(request.path, request.method, "")
  File "c:\users\prashant.kamble\appdata\local\programs\python\python36\lib\site-packages\sanic\router.py", line 469, in _get
    raise NotFound("Requested URL {} not found".format(url))
sanic.exceptions.NotFound: Requested URL /socket.io/ not found
2019-07-11 12:45:08,576 [ERROR]  Exception occurred while handling uri: 'http://localhost:5005/socket.io/?EIO=3&transport=polling&t=MlVuhzx'
Traceback (most recent call last):
  File "c:\users\prashant.kamble\appdata\local\programs\python\python36\lib\site-packages\sanic\app.py", line 893, in handle_request
    handler, args, kwargs, uri = self.router.get(request)
  File "c:\users\prashant.kamble\appdata\local\programs\python\python36\lib\site-packages\sanic\router.py", line 407, in get
    return self._get(request.path, request.method, "")
  File "c:\users\prashant.kamble\appdata\local\programs\python\python36\lib\site-packages\sanic\router.py", line 469, in _get
    raise NotFound("Requested URL {} not found".format(url))
sanic.exceptions.NotFound: Requested URL /socket.io/ not found
2019-07-11 12:47:17,003 [ERROR]  Exception occurred while handling uri: 'http://localhost:5005/socket.io/?EIO=3&transport=polling&t=MlVvBCZ'
Traceback (most recent call last):
  File "c:\users\prashant.kamble\appdata\local\programs\python\python36\lib\site-packages\sanic\app.py", line 893, in handle_request
    handler, args, kwargs, uri = self.router.get(request)
  File "c:\users\prashant.kamble\appdata\local\programs\python\python36\lib\site-packages\sanic\router.py", line 407, in get
    return self._get(request.path, request.method, "")
  File "c:\users\prashant.kamble\appdata\local\programs\python\python36\lib\site-packages\sanic\router.py", line 469, in _get
    raise NotFound("Requested URL {} not found".format(url))
sanic.exceptions.NotFound: Requested URL /socket.io/ not found
2019-07-11 12:47:55,069 [ERROR]  Exception occurred while handling uri: 'http://localhost:5005/socket.io/?EIO=3&transport=polling&t=MlVvClQ'
Traceback (most recent call last):
  File "c:\users\prashant.kamble\appdata\local\programs\python\python36\lib\site-packages\sanic\app.py", line 893, in handle_request
    handler, args, kwargs, uri = self.router.get(request)
  File "c:\users\prashant.kamble\appdata\local\programs\python\python36\lib\site-packages\sanic\router.py", line 407, in get
    return self._get(request.path, request.method, "")
  File "c:\users\prashant.kamble\appdata\local\programs\python\python36\lib\site-packages\sanic\router.py", line 469, in _get
    raise NotFound("Requested URL {} not found".format(url))
sanic.exceptions.NotFound: Requested URL /socket.io/ not found
2019-07-11 12:47:55,073 [ERROR]  Exception occurred while handling uri: 'http://localhost:5005/socket.io/?EIO=3&transport=polling&t=MlVvIs6'
Traceback (most recent call last):
  File "c:\users\prashant.kamble\appdata\local\programs\python\python36\lib\site-packages\sanic\app.py", line 893, in handle_request
    handler, args, kwargs, uri = self.router.get(request)
  File "c:\users\prashant.kamble\appdata\local\programs\python\python36\lib\site-packages\sanic\router.py", line 407, in get
    return self._get(request.path, request.method, "")
  File "c:\users\prashant.kamble\appdata\local\programs\python\python36\lib\site-packages\sanic\router.py", line 469, in _get
    raise NotFound("Requested URL {} not found".format(url))
sanic.exceptions.NotFound: Requested URL /socket.io/ not found
2019-07-11 12:48:01,594 [ERROR]  Exception occurred while handling uri: 'http://localhost:5005/socket.io/?EIO=3&transport=polling&t=MlVvM2H'
Traceback (most recent call last):
  File "c:\users\prashant.kamble\appdata\local\programs\python\python36\lib\site-packages\sanic\app.py", line 893, in handle_request
    handler, args, kwargs, uri = self.router.get(request)
  File "c:\users\prashant.kamble\appdata\local\programs\python\python36\lib\site-packages\sanic\router.py", line 407, in get
    return self._get(request.path, request.method, "")
  File "c:\users\prashant.kamble\appdata\local\programs\python\python36\lib\site-packages\sanic\router.py", line 469, in _get
    raise NotFound("Requested URL {} not found".format(url))
sanic.exceptions.NotFound: Requested URL /socket.io/ not found
2019-07-11 12:48:07,871 [ERROR]  Exception occurred while handling uri: 'http://localhost:5005/socket.io/?EIO=3&transport=polling&t=MlVvNe9'
Traceback (most recent call last):
  File "c:\users\prashant.kamble\appdata\local\programs\python\python36\lib\site-packages\sanic\app.py", line 893, in handle_request
    handler, args, kwargs, uri = self.router.get(request)
  File "c:\users\prashant.kamble\appdata\local\programs\python\python36\lib\site-packages\sanic\router.py", line 407, in get
    return self._get(request.path, request.method, "")
  File "c:\users\prashant.kamble\appdata\local\programs\python\python36\lib\site-packages\sanic\router.py", line 469, in _get
    raise NotFound("Requested URL {} not found".format(url))
sanic.exceptions.NotFound: Requested URL /socket.io/ not found
2019-07-11 12:48:35,989 [ERROR]  Exception occurred while handling uri: 'http://localhost:5005/socket.io/?EIO=3&transport=polling&t=MlVvPAE'
Traceback (most recent call last):
  File "c:\users\prashant.kamble\appdata\local\programs\python\python36\lib\site-packages\sanic\app.py", line 893, in handle_request
    handler, args, kwargs, uri = self.router.get(request)
  File "c:\users\prashant.kamble\appdata\local\programs\python\python36\lib\site-packages\sanic\router.py", line 407, in get
    return self._get(request.path, request.method, "")
  File "c:\users\prashant.kamble\appdata\local\programs\python\python36\lib\site-packages\sanic\router.py", line 469, in _get
    raise NotFound("Requested URL {} not found".format(url))
sanic.exceptions.NotFound: Requested URL /socket.io/ not found
2019-07-11 12:49:29,793 [ERROR]  Exception occurred while handling uri: 'http://localhost:5005/socket.io/?EIO=3&transport=polling&t=MlVvhGE'
Traceback (most recent call last):
  File "c:\users\prashant.kamble\appdata\local\programs\python\python36\lib\site-packages\sanic\app.py", line 893, in handle_request
    handler, args, kwargs, uri = self.router.get(request)
  File "c:\users\prashant.kamble\appdata\local\programs\python\python36\lib\site-packages\sanic\router.py", line 407, in get
    return self._get(request.path, request.method, "")
  File "c:\users\prashant.kamble\appdata\local\programs\python\python36\lib\site-packages\sanic\router.py", line 469, in _get
    raise NotFound("Requested URL {} not found".format(url))
sanic.exceptions.NotFound: Requested URL /socket.io/ not found
2019-07-11 12:50:58,905 [ERROR]  Exception occurred while handling uri: 'http://localhost:5005/socket.io/?EIO=3&transport=polling&t=MlVw1db'
Traceback (most recent call last):
  File "c:\users\prashant.kamble\appdata\local\programs\python\python36\lib\site-packages\sanic\app.py", line 893, in handle_request
    handler, args, kwargs, uri = self.router.get(request)
  File "c:\users\prashant.kamble\appdata\local\programs\python\python36\lib\site-packages\sanic\router.py", line 407, in get
    return self._get(request.path, request.method, "")
  File "c:\users\prashant.kamble\appdata\local\programs\python\python36\lib\site-packages\sanic\router.py", line 469, in _get
    raise NotFound("Requested URL {} not found".format(url))
sanic.exceptions.NotFound: Requested URL /socket.io/ not found
2019-07-11 12:51:04,227 [ERROR]  Exception occurred while handling uri: 'http://localhost:5005/socket.io/?EIO=3&transport=polling&t=MlVw2wg'
Traceback (most recent call last):
  File "c:\users\prashant.kamble\appdata\local\programs\python\python36\lib\site-packages\sanic\app.py", line 893, in handle_request
    handler, args, kwargs, uri = self.router.get(request)
  File "c:\users\prashant.kamble\appdata\local\programs\python\python36\lib\site-packages\sanic\router.py", line 407, in get
    return self._get(request.path, request.method, "")
  File "c:\users\prashant.kamble\appdata\local\programs\python\python36\lib\site-packages\sanic\router.py", line 469, in _get
    raise NotFound("Requested URL {} not found".format(url))
sanic.exceptions.NotFound: Requested URL /socket.io/ not found
2019-07-11 12:51:18,522 [ERROR]  Exception occurred while handling uri: 'http://localhost:5005/socket.io/?EIO=3&transport=polling&t=MlVw4Dq'
Traceback (most recent call last):
  File "c:\users\prashant.kamble\appdata\local\programs\python\python36\lib\site-packages\sanic\app.py", line 893, in handle_request
    handler, args, kwargs, uri = self.router.get(request)
  File "c:\users\prashant.kamble\appdata\local\programs\python\python36\lib\site-packages\sanic\router.py", line 407, in get
    return self._get(request.path, request.method, "")
  File "c:\users\prashant.kamble\appdata\local\programs\python\python36\lib\site-packages\sanic\router.py", line 469, in _get
    raise NotFound("Requested URL {} not found".format(url))
sanic.exceptions.NotFound: Requested URL /socket.io/ not found
2019-07-11 12:52:06,448 [ERROR]  Exception occurred while handling uri: 'http://localhost:5005/socket.io/?EIO=3&transport=polling&t=MlVwH-j'
Traceback (most recent call last):
  File "c:\users\prashant.kamble\appdata\local\programs\python\python36\lib\site-packages\sanic\app.py", line 893, in handle_request
    handler, args, kwargs, uri = self.router.get(request)
  File "c:\users\prashant.kamble\appdata\local\programs\python\python36\lib\site-packages\sanic\router.py", line 407, in get
    return self._get(request.path, request.method, "")
  File "c:\users\prashant.kamble\appdata\local\programs\python\python36\lib\site-packages\sanic\router.py", line 469, in _get
    raise NotFound("Requested URL {} not found".format(url))
sanic.exceptions.NotFound: Requested URL /socket.io/ not found
2019-07-11 12:52:11,460 [ERROR]  Exception occurred while handling uri: 'http://localhost:5005/socket.io/?EIO=3&transport=polling&t=MlVwJQ0'
Traceback (most recent call last):
  File "c:\users\prashant.kamble\appdata\local\programs\python\python36\lib\site-packages\sanic\app.py", line 893, in handle_request
    handler, args, kwargs, uri = self.router.get(request)
  File "c:\users\prashant.kamble\appdata\local\programs\python\python36\lib\site-packages\sanic\router.py", line 407, in get
    return self._get(request.path, request.method, "")
  File "c:\users\prashant.kamble\appdata\local\programs\python\python36\lib\site-packages\sanic\router.py", line 469, in _get
    raise NotFound("Requested URL {} not found".format(url))
sanic.exceptions.NotFound: Requested URL /socket.io/ not found
2019-07-11 12:52:26,526 [ERROR]  Exception occurred while handling uri: 'http://localhost:5005/socket.io/?EIO=3&transport=polling&t=MlVwKeI'
Traceback (most recent call last):
  File "c:\users\prashant.kamble\appdata\local\programs\python\python36\lib\site-packages\sanic\app.py", line 893, in handle_request
    handler, args, kwargs, uri = self.router.get(request)
  File "c:\users\prashant.kamble\appdata\local\programs\python\python36\lib\site-packages\sanic\router.py", line 407, in get
    return self._get(request.path, request.method, "")
  File "c:\users\prashant.kamble\appdata\local\programs\python\python36\lib\site-packages\sanic\router.py", line 469, in _get
    raise NotFound("Requested URL {} not found".format(url))
sanic.exceptions.NotFound: Requested URL /socket.io/ not found
2019-07-11 12:53:14,929 [ERROR]  Exception occurred while handling uri: 'http://localhost:5005/socket.io/?EIO=3&transport=polling&t=MlVwYbC'
Traceback (most recent call last):
  File "c:\users\prashant.kamble\appdata\local\programs\python\python36\lib\site-packages\sanic\app.py", line 893, in handle_request
    handler, args, kwargs, uri = self.router.get(request)
  File "c:\users\prashant.kamble\appdata\local\programs\python\python36\lib\site-packages\sanic\router.py", line 407, in get
    return self._get(request.path, request.method, "")
  File "c:\users\prashant.kamble\appdata\local\programs\python\python36\lib\site-packages\sanic\router.py", line 469, in _get
    raise NotFound("Requested URL {} not found".format(url))
sanic.exceptions.NotFound: Requested URL /socket.io/ not found
2019-07-11 12:53:20,864 [ERROR]  Exception occurred while handling uri: 'http://localhost:5005/socket.io/?EIO=3&transport=polling&t=MlVwa82'
Traceback (most recent call last):
  File "c:\users\prashant.kamble\appdata\local\programs\python\python36\lib\site-packages\sanic\app.py", line 893, in handle_request
    handler, args, kwargs, uri = self.router.get(request)
  File "c:\users\prashant.kamble\appdata\local\programs\python\python36\lib\site-packages\sanic\router.py", line 407, in get
    return self._get(request.path, request.method, "")
  File "c:\users\prashant.kamble\appdata\local\programs\python\python36\lib\site-packages\sanic\router.py", line 469, in _get
    raise NotFound("Requested URL {} not found".format(url))
sanic.exceptions.NotFound: Requested URL /socket.io/ not found
2019-07-12 11:11:49,556 [ERROR]  Exception occurred in one of response middleware handlers
Traceback (most recent call last):
  File "c:\users\prashant.kamble\appdata\local\programs\python\python36\lib\site-packages\sanic\app.py", line 958, in handle_request
    request, response
  File "c:\users\prashant.kamble\appdata\local\programs\python\python36\lib\site-packages\spf\framework.py", line 543, in _run_response_middleware
    _response = await _response
  File "c:\users\prashant.kamble\appdata\local\programs\python\python36\lib\site-packages\sanic_cors\extension.py", line 266, in unapplied_cors_response_middleware
    set_cors_headers(req, resp, context, res_options)
  File "c:\users\prashant.kamble\appdata\local\programs\python\python36\lib\site-packages\sanic_cors\core.py", line 248, in set_cors_headers
    if resp.headers is None:
AttributeError: 'list' object has no attribute 'headers'
2019-07-12 11:24:29,833 [ERROR]  Exception occurred while handling uri: 'http://localhost:5005/socket.io/?EIO=3&transport=polling&t=MlalpBD'
Traceback (most recent call last):
  File "c:\users\prashant.kamble\appdata\local\programs\python\python36\lib\site-packages\sanic\app.py", line 893, in handle_request
    handler, args, kwargs, uri = self.router.get(request)
  File "c:\users\prashant.kamble\appdata\local\programs\python\python36\lib\site-packages\sanic\router.py", line 407, in get
    return self._get(request.path, request.method, "")
  File "c:\users\prashant.kamble\appdata\local\programs\python\python36\lib\site-packages\sanic\router.py", line 469, in _get
    raise NotFound("Requested URL {} not found".format(url))
sanic.exceptions.NotFound: Requested URL /socket.io/ not found
2019-07-12 11:26:52,902 [ERROR]  Exception occurred while handling uri: unknown
NoneType: None
2019-07-12 11:29:51,102 [ERROR]  Exception occurred while handling uri: 'http://localhost:5005/socket.io/?EIO=3&transport=polling&t=Mlan057'
Traceback (most recent call last):
  File "c:\users\prashant.kamble\appdata\local\programs\python\python36\lib\site-packages\sanic\app.py", line 893, in handle_request
    handler, args, kwargs, uri = self.router.get(request)
  File "c:\users\prashant.kamble\appdata\local\programs\python\python36\lib\site-packages\sanic\router.py", line 407, in get
    return self._get(request.path, request.method, "")
  File "c:\users\prashant.kamble\appdata\local\programs\python\python36\lib\site-packages\sanic\router.py", line 469, in _get
    raise NotFound("Requested URL {} not found".format(url))
sanic.exceptions.NotFound: Requested URL /socket.io/ not found
2019-07-12 11:31:01,426 [ERROR]  Exception occurred while handling uri: 'http://localhost:5005/socket.io/?EIO=3&transport=polling&t=Mlan4UM'
Traceback (most recent call last):
  File "c:\users\prashant.kamble\appdata\local\programs\python\python36\lib\site-packages\sanic\app.py", line 893, in handle_request
    handler, args, kwargs, uri = self.router.get(request)
  File "c:\users\prashant.kamble\appdata\local\programs\python\python36\lib\site-packages\sanic\router.py", line 407, in get
    return self._get(request.path, request.method, "")
  File "c:\users\prashant.kamble\appdata\local\programs\python\python36\lib\site-packages\sanic\router.py", line 469, in _get
    raise NotFound("Requested URL {} not found".format(url))
sanic.exceptions.NotFound: Requested URL /socket.io/ not found
2019-07-12 11:31:01,429 [ERROR]  Exception occurred while handling uri: 'http://localhost:5005/socket.io/?EIO=3&transport=polling&t=MlanAqa'
Traceback (most recent call last):
  File "c:\users\prashant.kamble\appdata\local\programs\python\python36\lib\site-packages\sanic\app.py", line 893, in handle_request
    handler, args, kwargs, uri = self.router.get(request)
  File "c:\users\prashant.kamble\appdata\local\programs\python\python36\lib\site-packages\sanic\router.py", line 407, in get
    return self._get(request.path, request.method, "")
  File "c:\users\prashant.kamble\appdata\local\programs\python\python36\lib\site-packages\sanic\router.py", line 469, in _get
    raise NotFound("Requested URL {} not found".format(url))
sanic.exceptions.NotFound: Requested URL /socket.io/ not found
2019-07-12 11:31:01,430 [ERROR]  Exception occurred while handling uri: 'http://localhost:5005/socket.io/?EIO=3&transport=polling&t=MlanGxF'
Traceback (most recent call last):
  File "c:\users\prashant.kamble\appdata\local\programs\python\python36\lib\site-packages\sanic\app.py", line 893, in handle_request
    handler, args, kwargs, uri = self.router.get(request)
  File "c:\users\prashant.kamble\appdata\local\programs\python\python36\lib\site-packages\sanic\router.py", line 407, in get
    return self._get(request.path, request.method, "")
  File "c:\users\prashant.kamble\appdata\local\programs\python\python36\lib\site-packages\sanic\router.py", line 469, in _get
    raise NotFound("Requested URL {} not found".format(url))
sanic.exceptions.NotFound: Requested URL /socket.io/ not found
2019-07-12 11:42:10,040 [ERROR]  Exception occurred while handling uri: 'http://localhost:5005/socket.io/?EIO=3&transport=polling&t=MlanLa6'
Traceback (most recent call last):
  File "c:\users\prashant.kamble\appdata\local\programs\python\python36\lib\site-packages\sanic\app.py", line 893, in handle_request
    handler, args, kwargs, uri = self.router.get(request)
  File "c:\users\prashant.kamble\appdata\local\programs\python\python36\lib\site-packages\sanic\router.py", line 407, in get
    return self._get(request.path, request.method, "")
  File "c:\users\prashant.kamble\appdata\local\programs\python\python36\lib\site-packages\sanic\router.py", line 469, in _get
    raise NotFound("Requested URL {} not found".format(url))
sanic.exceptions.NotFound: Requested URL /socket.io/ not found
2019-07-12 11:42:10,043 [ERROR]  Exception occurred while handling uri: 'http://localhost:5005/socket.io/?EIO=3&transport=polling&t=MlanRwM'
Traceback (most recent call last):
  File "c:\users\prashant.kamble\appdata\local\programs\python\python36\lib\site-packages\sanic\app.py", line 893, in handle_request
    handler, args, kwargs, uri = self.router.get(request)
  File "c:\users\prashant.kamble\appdata\local\programs\python\python36\lib\site-packages\sanic\router.py", line 407, in get
    return self._get(request.path, request.method, "")
  File "c:\users\prashant.kamble\appdata\local\programs\python\python36\lib\site-packages\sanic\router.py", line 469, in _get
    raise NotFound("Requested URL {} not found".format(url))
sanic.exceptions.NotFound: Requested URL /socket.io/ not found
2019-07-12 11:42:10,045 [ERROR]  Exception occurred while handling uri: 'http://localhost:5005/socket.io/?EIO=3&transport=polling&t=MlanrJL'
Traceback (most recent call last):
  File "c:\users\prashant.kamble\appdata\local\programs\python\python36\lib\site-packages\sanic\app.py", line 893, in handle_request
    handler, args, kwargs, uri = self.router.get(request)
  File "c:\users\prashant.kamble\appdata\local\programs\python\python36\lib\site-packages\sanic\router.py", line 407, in get
    return self._get(request.path, request.method, "")
  File "c:\users\prashant.kamble\appdata\local\programs\python\python36\lib\site-packages\sanic\router.py", line 469, in _get
    raise NotFound("Requested URL {} not found".format(url))
sanic.exceptions.NotFound: Requested URL /socket.io/ not found
2019-07-12 11:42:10,048 [ERROR]  Exception occurred while handling uri: 'http://localhost:5005/socket.io/?EIO=3&transport=polling&t=Mlankz4'
Traceback (most recent call last):
  File "c:\users\prashant.kamble\appdata\local\programs\python\python36\lib\site-packages\sanic\app.py", line 893, in handle_request
    handler, args, kwargs, uri = self.router.get(request)
  File "c:\users\prashant.kamble\appdata\local\programs\python\python36\lib\site-packages\sanic\router.py", line 407, in get
    return self._get(request.path, request.method, "")
  File "c:\users\prashant.kamble\appdata\local\programs\python\python36\lib\site-packages\sanic\router.py", line 469, in _get
    raise NotFound("Requested URL {} not found".format(url))
sanic.exceptions.NotFound: Requested URL /socket.io/ not found
2019-07-12 11:42:10,050 [ERROR]  Exception occurred while handling uri: 'http://localhost:5005/socket.io/?EIO=3&transport=polling&t=MlanYGb'
Traceback (most recent call last):
  File "c:\users\prashant.kamble\appdata\local\programs\python\python36\lib\site-packages\sanic\app.py", line 893, in handle_request
    handler, args, kwargs, uri = self.router.get(request)
  File "c:\users\prashant.kamble\appdata\local\programs\python\python36\lib\site-packages\sanic\router.py", line 407, in get
    return self._get(request.path, request.method, "")
  File "c:\users\prashant.kamble\appdata\local\programs\python\python36\lib\site-packages\sanic\router.py", line 469, in _get
    raise NotFound("Requested URL {} not found".format(url))
sanic.exceptions.NotFound: Requested URL /socket.io/ not found
2019-07-12 11:42:10,052 [ERROR]  Exception occurred while handling uri: 'http://localhost:5005/socket.io/?EIO=3&transport=polling&t=Mlanecs'
Traceback (most recent call last):
  File "c:\users\prashant.kamble\appdata\local\programs\python\python36\lib\site-packages\sanic\app.py", line 893, in handle_request
    handler, args, kwargs, uri = self.router.get(request)
  File "c:\users\prashant.kamble\appdata\local\programs\python\python36\lib\site-packages\sanic\router.py", line 407, in get
    return self._get(request.path, request.method, "")
  File "c:\users\prashant.kamble\appdata\local\programs\python\python36\lib\site-packages\sanic\router.py", line 469, in _get
    raise NotFound("Requested URL {} not found".format(url))
sanic.exceptions.NotFound: Requested URL /socket.io/ not found
2019-07-12 11:42:10,055 [ERROR]  Exception occurred while handling uri: 'http://localhost:5005/socket.io/?EIO=3&transport=polling&t=Mlanxfa'
Traceback (most recent call last):
  File "c:\users\prashant.kamble\appdata\local\programs\python\python36\lib\site-packages\sanic\app.py", line 893, in handle_request
    handler, args, kwargs, uri = self.router.get(request)
  File "c:\users\prashant.kamble\appdata\local\programs\python\python36\lib\site-packages\sanic\router.py", line 407, in get
    return self._get(request.path, request.method, "")
  File "c:\users\prashant.kamble\appdata\local\programs\python\python36\lib\site-packages\sanic\router.py", line 469, in _get
    raise NotFound("Requested URL {} not found".format(url))
sanic.exceptions.NotFound: Requested URL /socket.io/ not found
2019-07-12 11:42:10,059 [ERROR]  Exception occurred while handling uri: 'http://localhost:5005/socket.io/?EIO=3&transport=polling&t=Mlao1mF'
Traceback (most recent call last):
  File "c:\users\prashant.kamble\appdata\local\programs\python\python36\lib\site-packages\sanic\app.py", line 893, in handle_request
    handler, args, kwargs, uri = self.router.get(request)
  File "c:\users\prashant.kamble\appdata\local\programs\python\python36\lib\site-packages\sanic\router.py", line 407, in get
    return self._get(request.path, request.method, "")
  File "c:\users\prashant.kamble\appdata\local\programs\python\python36\lib\site-packages\sanic\router.py", line 469, in _get
    raise NotFound("Requested URL {} not found".format(url))
sanic.exceptions.NotFound: Requested URL /socket.io/ not found
2019-07-12 11:42:10,061 [ERROR]  Exception occurred while handling uri: 'http://localhost:5005/socket.io/?EIO=3&transport=polling&t=Mlao86V'
Traceback (most recent call last):
  File "c:\users\prashant.kamble\appdata\local\programs\python\python36\lib\site-packages\sanic\app.py", line 893, in handle_request
    handler, args, kwargs, uri = self.router.get(request)
  File "c:\users\prashant.kamble\appdata\local\programs\python\python36\lib\site-packages\sanic\router.py", line 407, in get
    return self._get(request.path, request.method, "")
  File "c:\users\prashant.kamble\appdata\local\programs\python\python36\lib\site-packages\sanic\router.py", line 469, in _get
    raise NotFound("Requested URL {} not found".format(url))
sanic.exceptions.NotFound: Requested URL /socket.io/ not found
2019-07-12 11:42:10,063 [ERROR]  Exception occurred while handling uri: 'http://localhost:5005/socket.io/?EIO=3&transport=polling&t=MlaoKo-'
Traceback (most recent call last):
  File "c:\users\prashant.kamble\appdata\local\programs\python\python36\lib\site-packages\sanic\app.py", line 893, in handle_request
    handler, args, kwargs, uri = self.router.get(request)
  File "c:\users\prashant.kamble\appdata\local\programs\python\python36\lib\site-packages\sanic\router.py", line 407, in get
    return self._get(request.path, request.method, "")
  File "c:\users\prashant.kamble\appdata\local\programs\python\python36\lib\site-packages\sanic\router.py", line 469, in _get
    raise NotFound("Requested URL {} not found".format(url))
sanic.exceptions.NotFound: Requested URL /socket.io/ not found
2019-07-12 11:42:10,065 [ERROR]  Exception occurred while handling uri: 'http://localhost:5005/socket.io/?EIO=3&transport=polling&t=MlaoESk'
Traceback (most recent call last):
  File "c:\users\prashant.kamble\appdata\local\programs\python\python36\lib\site-packages\sanic\app.py", line 893, in handle_request
    handler, args, kwargs, uri = self.router.get(request)
  File "c:\users\prashant.kamble\appdata\local\programs\python\python36\lib\site-packages\sanic\router.py", line 407, in get
    return self._get(request.path, request.method, "")
  File "c:\users\prashant.kamble\appdata\local\programs\python\python36\lib\site-packages\sanic\router.py", line 469, in _get
    raise NotFound("Requested URL {} not found".format(url))
sanic.exceptions.NotFound: Requested URL /socket.io/ not found
2019-07-12 11:42:10,068 [ERROR]  Exception occurred while handling uri: 'http://localhost:5005/socket.io/?EIO=3&transport=polling&t=MlaoR9C'
Traceback (most recent call last):
  File "c:\users\prashant.kamble\appdata\local\programs\python\python36\lib\site-packages\sanic\app.py", line 893, in handle_request
    handler, args, kwargs, uri = self.router.get(request)
  File "c:\users\prashant.kamble\appdata\local\programs\python\python36\lib\site-packages\sanic\router.py", line 407, in get
    return self._get(request.path, request.method, "")
  File "c:\users\prashant.kamble\appdata\local\programs\python\python36\lib\site-packages\sanic\router.py", line 469, in _get
    raise NotFound("Requested URL {} not found".format(url))
sanic.exceptions.NotFound: Requested URL /socket.io/ not found
2019-07-12 11:42:10,071 [ERROR]  Exception occurred while handling uri: 'http://localhost:5005/socket.io/?EIO=3&transport=polling&t=Mlaodrk'
Traceback (most recent call last):
  File "c:\users\prashant.kamble\appdata\local\programs\python\python36\lib\site-packages\sanic\app.py", line 893, in handle_request
    handler, args, kwargs, uri = self.router.get(request)
  File "c:\users\prashant.kamble\appdata\local\programs\python\python36\lib\site-packages\sanic\router.py", line 407, in get
    return self._get(request.path, request.method, "")
  File "c:\users\prashant.kamble\appdata\local\programs\python\python36\lib\site-packages\sanic\router.py", line 469, in _get
    raise NotFound("Requested URL {} not found".format(url))
sanic.exceptions.NotFound: Requested URL /socket.io/ not found
2019-07-12 11:42:10,073 [ERROR]  Exception occurred while handling uri: 'http://localhost:5005/socket.io/?EIO=3&transport=polling&t=MlaokC7'
Traceback (most recent call last):
  File "c:\users\prashant.kamble\appdata\local\programs\python\python36\lib\site-packages\sanic\app.py", line 893, in handle_request
    handler, args, kwargs, uri = self.router.get(request)
  File "c:\users\prashant.kamble\appdata\local\programs\python\python36\lib\site-packages\sanic\router.py", line 407, in get
    return self._get(request.path, request.method, "")
  File "c:\users\prashant.kamble\appdata\local\programs\python\python36\lib\site-packages\sanic\router.py", line 469, in _get
    raise NotFound("Requested URL {} not found".format(url))
sanic.exceptions.NotFound: Requested URL /socket.io/ not found
2019-07-12 11:42:10,076 [ERROR]  Exception occurred while handling uri: 'http://localhost:5005/socket.io/?EIO=3&transport=polling&t=MlaoqYE'
Traceback (most recent call last):
  File "c:\users\prashant.kamble\appdata\local\programs\python\python36\lib\site-packages\sanic\app.py", line 893, in handle_request
    handler, args, kwargs, uri = self.router.get(request)
  File "c:\users\prashant.kamble\appdata\local\programs\python\python36\lib\site-packages\sanic\router.py", line 407, in get
    return self._get(request.path, request.method, "")
  File "c:\users\prashant.kamble\appdata\local\programs\python\python36\lib\site-packages\sanic\router.py", line 469, in _get
    raise NotFound("Requested URL {} not found".format(url))
sanic.exceptions.NotFound: Requested URL /socket.io/ not found
2019-07-12 11:42:10,079 [ERROR]  Exception occurred while handling uri: 'http://localhost:5005/socket.io/?EIO=3&transport=polling&t=MlaoXVS'
Traceback (most recent call last):
  File "c:\users\prashant.kamble\appdata\local\programs\python\python36\lib\site-packages\sanic\app.py", line 893, in handle_request
    handler, args, kwargs, uri = self.router.get(request)
  File "c:\users\prashant.kamble\appdata\local\programs\python\python36\lib\site-packages\sanic\router.py", line 407, in get
    return self._get(request.path, request.method, "")
  File "c:\users\prashant.kamble\appdata\local\programs\python\python36\lib\site-packages\sanic\router.py", line 469, in _get
    raise NotFound("Requested URL {} not found".format(url))
sanic.exceptions.NotFound: Requested URL /socket.io/ not found
2019-07-12 11:42:10,081 [ERROR]  Exception occurred while handling uri: 'http://localhost:5005/socket.io/?EIO=3&transport=polling&t=MlaowuT'
Traceback (most recent call last):
  File "c:\users\prashant.kamble\appdata\local\programs\python\python36\lib\site-packages\sanic\app.py", line 893, in handle_request
    handler, args, kwargs, uri = self.router.get(request)
  File "c:\users\prashant.kamble\appdata\local\programs\python\python36\lib\site-packages\sanic\router.py", line 407, in get
    return self._get(request.path, request.method, "")
  File "c:\users\prashant.kamble\appdata\local\programs\python\python36\lib\site-packages\sanic\router.py", line 469, in _get
    raise NotFound("Requested URL {} not found".format(url))
sanic.exceptions.NotFound: Requested URL /socket.io/ not found
2019-07-12 11:42:10,085 [ERROR]  Exception occurred while handling uri: 'http://localhost:5005/socket.io/?EIO=3&transport=polling&t=Mlap7az'
Traceback (most recent call last):
  File "c:\users\prashant.kamble\appdata\local\programs\python\python36\lib\site-packages\sanic\app.py", line 893, in handle_request
    handler, args, kwargs, uri = self.router.get(request)
  File "c:\users\prashant.kamble\appdata\local\programs\python\python36\lib\site-packages\sanic\router.py", line 407, in get
    return self._get(request.path, request.method, "")
  File "c:\users\prashant.kamble\appdata\local\programs\python\python36\lib\site-packages\sanic\router.py", line 469, in _get
    raise NotFound("Requested URL {} not found".format(url))
sanic.exceptions.NotFound: Requested URL /socket.io/ not found
2019-07-12 11:42:10,087 [ERROR]  Exception occurred while handling uri: 'http://localhost:5005/socket.io/?EIO=3&transport=polling&t=MlapDxC'
Traceback (most recent call last):
  File "c:\users\prashant.kamble\appdata\local\programs\python\python36\lib\site-packages\sanic\app.py", line 893, in handle_request
    handler, args, kwargs, uri = self.router.get(request)
  File "c:\users\prashant.kamble\appdata\local\programs\python\python36\lib\site-packages\sanic\router.py", line 407, in get
    return self._get(request.path, request.method, "")
  File "c:\users\prashant.kamble\appdata\local\programs\python\python36\lib\site-packages\sanic\router.py", line 469, in _get
    raise NotFound("Requested URL {} not found".format(url))
sanic.exceptions.NotFound: Requested URL /socket.io/ not found
2019-07-12 11:42:10,089 [ERROR]  Exception occurred while handling uri: 'http://localhost:5005/socket.io/?EIO=3&transport=polling&t=MlapK1u'
Traceback (most recent call last):
  File "c:\users\prashant.kamble\appdata\local\programs\python\python36\lib\site-packages\sanic\app.py", line 893, in handle_request
    handler, args, kwargs, uri = self.router.get(request)
  File "c:\users\prashant.kamble\appdata\local\programs\python\python36\lib\site-packages\sanic\router.py", line 407, in get
    return self._get(request.path, request.method, "")
  File "c:\users\prashant.kamble\appdata\local\programs\python\python36\lib\site-packages\sanic\router.py", line 469, in _get
    raise NotFound("Requested URL {} not found".format(url))
sanic.exceptions.NotFound: Requested URL /socket.io/ not found
2019-07-12 11:42:10,091 [ERROR]  Exception occurred while handling uri: 'http://localhost:5005/socket.io/?EIO=3&transport=polling&t=Mlap1Ej'
Traceback (most recent call last):
  File "c:\users\prashant.kamble\appdata\local\programs\python\python36\lib\site-packages\sanic\app.py", line 893, in handle_request
    handler, args, kwargs, uri = self.router.get(request)
  File "c:\users\prashant.kamble\appdata\local\programs\python\python36\lib\site-packages\sanic\router.py", line 407, in get
    return self._get(request.path, request.method, "")
  File "c:\users\prashant.kamble\appdata\local\programs\python\python36\lib\site-packages\sanic\router.py", line 469, in _get
    raise NotFound("Requested URL {} not found".format(url))
sanic.exceptions.NotFound: Requested URL /socket.io/ not found
2019-07-12 11:42:10,094 [ERROR]  Exception occurred while handling uri: 'http://localhost:5005/socket.io/?EIO=3&transport=polling&t=MlapQO5'
Traceback (most recent call last):
  File "c:\users\prashant.kamble\appdata\local\programs\python\python36\lib\site-packages\sanic\app.py", line 893, in handle_request
    handler, args, kwargs, uri = self.router.get(request)
  File "c:\users\prashant.kamble\appdata\local\programs\python\python36\lib\site-packages\sanic\router.py", line 407, in get
    return self._get(request.path, request.method, "")
  File "c:\users\prashant.kamble\appdata\local\programs\python\python36\lib\site-packages\sanic\router.py", line 469, in _get
    raise NotFound("Requested URL {} not found".format(url))
sanic.exceptions.NotFound: Requested URL /socket.io/ not found
2019-07-12 11:42:10,097 [ERROR]  Exception occurred while handling uri: 'http://localhost:5005/socket.io/?EIO=3&transport=polling&t=Mlapd4b'
Traceback (most recent call last):
  File "c:\users\prashant.kamble\appdata\local\programs\python\python36\lib\site-packages\sanic\app.py", line 893, in handle_request
    handler, args, kwargs, uri = self.router.get(request)
  File "c:\users\prashant.kamble\appdata\local\programs\python\python36\lib\site-packages\sanic\router.py", line 407, in get
    return self._get(request.path, request.method, "")
  File "c:\users\prashant.kamble\appdata\local\programs\python\python36\lib\site-packages\sanic\router.py", line 469, in _get
    raise NotFound("Requested URL {} not found".format(url))
sanic.exceptions.NotFound: Requested URL /socket.io/ not found
2019-07-12 11:42:10,099 [ERROR]  Exception occurred while handling uri: 'http://localhost:5005/socket.io/?EIO=3&transport=polling&t=MlapjQq'
Traceback (most recent call last):
  File "c:\users\prashant.kamble\appdata\local\programs\python\python36\lib\site-packages\sanic\app.py", line 893, in handle_request
    handler, args, kwargs, uri = self.router.get(request)
  File "c:\users\prashant.kamble\appdata\local\programs\python\python36\lib\site-packages\sanic\router.py", line 407, in get
    return self._get(request.path, request.method, "")
  File "c:\users\prashant.kamble\appdata\local\programs\python\python36\lib\site-packages\sanic\router.py", line 469, in _get
    raise NotFound("Requested URL {} not found".format(url))
sanic.exceptions.NotFound: Requested URL /socket.io/ not found
2019-07-12 11:42:10,102 [ERROR]  Exception occurred while handling uri: 'http://localhost:5005/socket.io/?EIO=3&transport=polling&t=Mlappn5'
Traceback (most recent call last):
  File "c:\users\prashant.kamble\appdata\local\programs\python\python36\lib\site-packages\sanic\app.py", line 893, in handle_request
    handler, args, kwargs, uri = self.router.get(request)
  File "c:\users\prashant.kamble\appdata\local\programs\python\python36\lib\site-packages\sanic\router.py", line 407, in get
    return self._get(request.path, request.method, "")
  File "c:\users\prashant.kamble\appdata\local\programs\python\python36\lib\site-packages\sanic\router.py", line 469, in _get
    raise NotFound("Requested URL {} not found".format(url))
sanic.exceptions.NotFound: Requested URL /socket.io/ not found
2019-07-12 11:42:10,104 [ERROR]  Exception occurred while handling uri: 'http://localhost:5005/socket.io/?EIO=3&transport=polling&t=MlapWkM'
Traceback (most recent call last):
  File "c:\users\prashant.kamble\appdata\local\programs\python\python36\lib\site-packages\sanic\app.py", line 893, in handle_request
    handler, args, kwargs, uri = self.router.get(request)
  File "c:\users\prashant.kamble\appdata\local\programs\python\python36\lib\site-packages\sanic\router.py", line 407, in get
    return self._get(request.path, request.method, "")
  File "c:\users\prashant.kamble\appdata\local\programs\python\python36\lib\site-packages\sanic\router.py", line 469, in _get
    raise NotFound("Requested URL {} not found".format(url))
sanic.exceptions.NotFound: Requested URL /socket.io/ not found
2019-07-12 11:42:21,370 [ERROR]  Exception occurred while handling uri: 'http://localhost:5005/socket.io/?EIO=3&transport=polling&t=MlapuvE'
Traceback (most recent call last):
  File "c:\users\prashant.kamble\appdata\local\programs\python\python36\lib\site-packages\sanic\app.py", line 893, in handle_request
    handler, args, kwargs, uri = self.router.get(request)
  File "c:\users\prashant.kamble\appdata\local\programs\python\python36\lib\site-packages\sanic\router.py", line 407, in get
    return self._get(request.path, request.method, "")
  File "c:\users\prashant.kamble\appdata\local\programs\python\python36\lib\site-packages\sanic\router.py", line 469, in _get
    raise NotFound("Requested URL {} not found".format(url))
sanic.exceptions.NotFound: Requested URL /socket.io/ not found
2019-07-12 11:42:37,731 [ERROR]  Exception occurred while handling uri: 'http://localhost:5005/socket.io/?EIO=3&transport=polling&t=Mlapxb6'
Traceback (most recent call last):
  File "c:\users\prashant.kamble\appdata\local\programs\python\python36\lib\site-packages\sanic\app.py", line 893, in handle_request
    handler, args, kwargs, uri = self.router.get(request)
  File "c:\users\prashant.kamble\appdata\local\programs\python\python36\lib\site-packages\sanic\router.py", line 407, in get
    return self._get(request.path, request.method, "")
  File "c:\users\prashant.kamble\appdata\local\programs\python\python36\lib\site-packages\sanic\router.py", line 469, in _get
    raise NotFound("Requested URL {} not found".format(url))
sanic.exceptions.NotFound: Requested URL /socket.io/ not found
2019-07-12 11:43:02,769 [ERROR]  Exception occurred while handling uri: 'http://localhost:5005/socket.io/?EIO=3&transport=polling&t=Mlap_V7'
Traceback (most recent call last):
  File "c:\users\prashant.kamble\appdata\local\programs\python\python36\lib\site-packages\sanic\app.py", line 893, in handle_request
    handler, args, kwargs, uri = self.router.get(request)
  File "c:\users\prashant.kamble\appdata\local\programs\python\python36\lib\site-packages\sanic\router.py", line 407, in get
    return self._get(request.path, request.method, "")
  File "c:\users\prashant.kamble\appdata\local\programs\python\python36\lib\site-packages\sanic\router.py", line 469, in _get
    raise NotFound("Requested URL {} not found".format(url))
sanic.exceptions.NotFound: Requested URL /socket.io/ not found
2019-07-12 11:43:37,352 [ERROR]  Exception occurred while handling uri: 'http://localhost:5005/socket.io/?EIO=3&transport=polling&t=Mlaq5bk'
Traceback (most recent call last):
  File "c:\users\prashant.kamble\appdata\local\programs\python\python36\lib\site-packages\sanic\app.py", line 893, in handle_request
    handler, args, kwargs, uri = self.router.get(request)
  File "c:\users\prashant.kamble\appdata\local\programs\python\python36\lib\site-packages\sanic\router.py", line 407, in get
    return self._get(request.path, request.method, "")
  File "c:\users\prashant.kamble\appdata\local\programs\python\python36\lib\site-packages\sanic\router.py", line 469, in _get
    raise NotFound("Requested URL {} not found".format(url))
sanic.exceptions.NotFound: Requested URL /socket.io/ not found
2019-07-12 11:43:37,353 [ERROR]  Exception occurred while handling uri: 'http://localhost:5005/socket.io/?EIO=3&transport=polling&t=MlaqBxy'
Traceback (most recent call last):
  File "c:\users\prashant.kamble\appdata\local\programs\python\python36\lib\site-packages\sanic\app.py", line 893, in handle_request
    handler, args, kwargs, uri = self.router.get(request)
  File "c:\users\prashant.kamble\appdata\local\programs\python\python36\lib\site-packages\sanic\router.py", line 407, in get
    return self._get(request.path, request.method, "")
  File "c:\users\prashant.kamble\appdata\local\programs\python\python36\lib\site-packages\sanic\router.py", line 469, in _get
    raise NotFound("Requested URL {} not found".format(url))
sanic.exceptions.NotFound: Requested URL /socket.io/ not found
2019-07-12 11:43:43,311 [ERROR]  Exception occurred while handling uri: 'http://localhost:5005/socket.io/?EIO=3&transport=polling&t=MlaqE8b'
Traceback (most recent call last):
  File "c:\users\prashant.kamble\appdata\local\programs\python\python36\lib\site-packages\sanic\app.py", line 893, in handle_request
    handler, args, kwargs, uri = self.router.get(request)
  File "c:\users\prashant.kamble\appdata\local\programs\python\python36\lib\site-packages\sanic\router.py", line 407, in get
    return self._get(request.path, request.method, "")
  File "c:\users\prashant.kamble\appdata\local\programs\python\python36\lib\site-packages\sanic\router.py", line 469, in _get
    raise NotFound("Requested URL {} not found".format(url))
sanic.exceptions.NotFound: Requested URL /socket.io/ not found
2019-07-12 11:43:52,208 [ERROR]  Exception occurred while handling uri: 'http://localhost:5005/socket.io/?EIO=3&transport=polling&t=MlaqFcO'
Traceback (most recent call last):
  File "c:\users\prashant.kamble\appdata\local\programs\python\python36\lib\site-packages\sanic\app.py", line 893, in handle_request
    handler, args, kwargs, uri = self.router.get(request)
  File "c:\users\prashant.kamble\appdata\local\programs\python\python36\lib\site-packages\sanic\router.py", line 407, in get
    return self._get(request.path, request.method, "")
  File "c:\users\prashant.kamble\appdata\local\programs\python\python36\lib\site-packages\sanic\router.py", line 469, in _get
    raise NotFound("Requested URL {} not found".format(url))
sanic.exceptions.NotFound: Requested URL /socket.io/ not found
2019-07-12 11:43:58,946 [ERROR]  Exception occurred while handling uri: 'http://localhost:5005/socket.io/?EIO=3&transport=polling&t=MlaqHoz'
Traceback (most recent call last):
  File "c:\users\prashant.kamble\appdata\local\programs\python\python36\lib\site-packages\sanic\app.py", line 893, in handle_request
    handler, args, kwargs, uri = self.router.get(request)
  File "c:\users\prashant.kamble\appdata\local\programs\python\python36\lib\site-packages\sanic\router.py", line 407, in get
    return self._get(request.path, request.method, "")
  File "c:\users\prashant.kamble\appdata\local\programs\python\python36\lib\site-packages\sanic\router.py", line 469, in _get
    raise NotFound("Requested URL {} not found".format(url))
sanic.exceptions.NotFound: Requested URL /socket.io/ not found
2019-07-12 11:45:02,811 [ERROR]  Exception occurred while handling uri: unknown
NoneType: None
2019-07-12 11:46:06,097 [ERROR]  Exception occurred while handling uri: 'http://localhost:5005/socket.io/?EIO=3&transport=polling&t=MlaqmZk'
Traceback (most recent call last):
  File "c:\users\prashant.kamble\appdata\local\programs\python\python36\lib\site-packages\sanic\app.py", line 893, in handle_request
    handler, args, kwargs, uri = self.router.get(request)
  File "c:\users\prashant.kamble\appdata\local\programs\python\python36\lib\site-packages\sanic\router.py", line 407, in get
    return self._get(request.path, request.method, "")
  File "c:\users\prashant.kamble\appdata\local\programs\python\python36\lib\site-packages\sanic\router.py", line 469, in _get
    raise NotFound("Requested URL {} not found".format(url))
sanic.exceptions.NotFound: Requested URL /socket.io/ not found
2019-07-12 11:46:13,861 [ERROR]  Exception occurred while handling uri: 'http://localhost:5005/socket.io/?EIO=3&transport=polling&t=MlaqoWj'
Traceback (most recent call last):
  File "c:\users\prashant.kamble\appdata\local\programs\python\python36\lib\site-packages\sanic\app.py", line 893, in handle_request
    handler, args, kwargs, uri = self.router.get(request)
  File "c:\users\prashant.kamble\appdata\local\programs\python\python36\lib\site-packages\sanic\router.py", line 407, in get
    return self._get(request.path, request.method, "")
  File "c:\users\prashant.kamble\appdata\local\programs\python\python36\lib\site-packages\sanic\router.py", line 469, in _get
    raise NotFound("Requested URL {} not found".format(url))
sanic.exceptions.NotFound: Requested URL /socket.io/ not found
2019-07-12 11:46:35,592 [ERROR]  Exception occurred while handling uri: 'http://localhost:5005/socket.io/?EIO=3&transport=polling&t=MlaqqE5'
Traceback (most recent call last):
  File "c:\users\prashant.kamble\appdata\local\programs\python\python36\lib\site-packages\sanic\app.py", line 893, in handle_request
    handler, args, kwargs, uri = self.router.get(request)
  File "c:\users\prashant.kamble\appdata\local\programs\python\python36\lib\site-packages\sanic\router.py", line 407, in get
    return self._get(request.path, request.method, "")
  File "c:\users\prashant.kamble\appdata\local\programs\python\python36\lib\site-packages\sanic\router.py", line 469, in _get
    raise NotFound("Requested URL {} not found".format(url))
sanic.exceptions.NotFound: Requested URL /socket.io/ not found
2019-07-12 11:46:48,541 [ERROR]  Exception occurred while handling uri: 'http://localhost:5005/socket.io/?EIO=3&transport=polling&t=Mlaqvbs'
Traceback (most recent call last):
  File "c:\users\prashant.kamble\appdata\local\programs\python\python36\lib\site-packages\sanic\app.py", line 893, in handle_request
    handler, args, kwargs, uri = self.router.get(request)
  File "c:\users\prashant.kamble\appdata\local\programs\python\python36\lib\site-packages\sanic\router.py", line 407, in get
    return self._get(request.path, request.method, "")
  File "c:\users\prashant.kamble\appdata\local\programs\python\python36\lib\site-packages\sanic\router.py", line 469, in _get
    raise NotFound("Requested URL {} not found".format(url))
sanic.exceptions.NotFound: Requested URL /socket.io/ not found
2019-07-12 11:46:59,424 [ERROR]  Exception occurred while handling uri: 'http://localhost:5005/socket.io/?EIO=3&transport=polling&t=Mlaqymz'
Traceback (most recent call last):
  File "c:\users\prashant.kamble\appdata\local\programs\python\python36\lib\site-packages\sanic\app.py", line 893, in handle_request
    handler, args, kwargs, uri = self.router.get(request)
  File "c:\users\prashant.kamble\appdata\local\programs\python\python36\lib\site-packages\sanic\router.py", line 407, in get
    return self._get(request.path, request.method, "")
  File "c:\users\prashant.kamble\appdata\local\programs\python\python36\lib\site-packages\sanic\router.py", line 469, in _get
    raise NotFound("Requested URL {} not found".format(url))
sanic.exceptions.NotFound: Requested URL /socket.io/ not found
2019-07-12 11:48:49,793 [ERROR]  Exception occurred while handling uri: unknown
NoneType: None
2019-07-12 11:49:36,339 [ERROR]  Exception occurred while handling uri: 'http://localhost:5005/socket.io/?EIO=3&transport=polling&t=Mlara4b'
Traceback (most recent call last):
  File "c:\users\prashant.kamble\appdata\local\programs\python\python36\lib\site-packages\sanic\app.py", line 893, in handle_request
    handler, args, kwargs, uri = self.router.get(request)
  File "c:\users\prashant.kamble\appdata\local\programs\python\python36\lib\site-packages\sanic\router.py", line 407, in get
    return self._get(request.path, request.method, "")
  File "c:\users\prashant.kamble\appdata\local\programs\python\python36\lib\site-packages\sanic\router.py", line 469, in _get
    raise NotFound("Requested URL {} not found".format(url))
sanic.exceptions.NotFound: Requested URL /socket.io/ not found
2019-07-12 11:49:43,388 [ERROR]  Exception occurred while handling uri: 'http://localhost:5005/socket.io/?EIO=3&transport=polling&t=Mlarc1b'
Traceback (most recent call last):
  File "c:\users\prashant.kamble\appdata\local\programs\python\python36\lib\site-packages\sanic\app.py", line 893, in handle_request
    handler, args, kwargs, uri = self.router.get(request)
  File "c:\users\prashant.kamble\appdata\local\programs\python\python36\lib\site-packages\sanic\router.py", line 407, in get
    return self._get(request.path, request.method, "")
  File "c:\users\prashant.kamble\appdata\local\programs\python\python36\lib\site-packages\sanic\router.py", line 469, in _get
    raise NotFound("Requested URL {} not found".format(url))
sanic.exceptions.NotFound: Requested URL /socket.io/ not found
2019-07-12 11:51:42,392 [ERROR]  Exception occurred while handling uri: 'http://localhost:5005/socket.io/?EIO=3&transport=polling&t=Mlas34-'
Traceback (most recent call last):
  File "c:\users\prashant.kamble\appdata\local\programs\python\python36\lib\site-packages\sanic\app.py", line 893, in handle_request
    handler, args, kwargs, uri = self.router.get(request)
  File "c:\users\prashant.kamble\appdata\local\programs\python\python36\lib\site-packages\sanic\router.py", line 407, in get
    return self._get(request.path, request.method, "")
  File "c:\users\prashant.kamble\appdata\local\programs\python\python36\lib\site-packages\sanic\router.py", line 469, in _get
    raise NotFound("Requested URL {} not found".format(url))
sanic.exceptions.NotFound: Requested URL /socket.io/ not found
2019-07-12 11:51:51,455 [ERROR]  Exception occurred while handling uri: 'http://localhost:5005/socket.io/?EIO=3&transport=polling&t=Mlas4Yl'
Traceback (most recent call last):
  File "c:\users\prashant.kamble\appdata\local\programs\python\python36\lib\site-packages\sanic\app.py", line 893, in handle_request
    handler, args, kwargs, uri = self.router.get(request)
  File "c:\users\prashant.kamble\appdata\local\programs\python\python36\lib\site-packages\sanic\router.py", line 407, in get
    return self._get(request.path, request.method, "")
  File "c:\users\prashant.kamble\appdata\local\programs\python\python36\lib\site-packages\sanic\router.py", line 469, in _get
    raise NotFound("Requested URL {} not found".format(url))
sanic.exceptions.NotFound: Requested URL /socket.io/ not found
2019-07-12 11:52:01,421 [ERROR]  Exception occurred while handling uri: 'http://localhost:5005/socket.io/?EIO=3&transport=polling&t=Mlas6lM'
Traceback (most recent call last):
  File "c:\users\prashant.kamble\appdata\local\programs\python\python36\lib\site-packages\sanic\app.py", line 893, in handle_request
    handler, args, kwargs, uri = self.router.get(request)
  File "c:\users\prashant.kamble\appdata\local\programs\python\python36\lib\site-packages\sanic\router.py", line 407, in get
    return self._get(request.path, request.method, "")
  File "c:\users\prashant.kamble\appdata\local\programs\python\python36\lib\site-packages\sanic\router.py", line 469, in _get
    raise NotFound("Requested URL {} not found".format(url))
sanic.exceptions.NotFound: Requested URL /socket.io/ not found
2019-07-12 11:53:12,386 [ERROR]  Exception occurred while handling uri: 'http://localhost:5005/socket.io/?EIO=3&transport=polling&t=Mlas9Ba'
Traceback (most recent call last):
  File "c:\users\prashant.kamble\appdata\local\programs\python\python36\lib\site-packages\sanic\app.py", line 893, in handle_request
    handler, args, kwargs, uri = self.router.get(request)
  File "c:\users\prashant.kamble\appdata\local\programs\python\python36\lib\site-packages\sanic\router.py", line 407, in get
    return self._get(request.path, request.method, "")
  File "c:\users\prashant.kamble\appdata\local\programs\python\python36\lib\site-packages\sanic\router.py", line 469, in _get
    raise NotFound("Requested URL {} not found".format(url))
sanic.exceptions.NotFound: Requested URL /socket.io/ not found
2019-07-12 11:53:12,388 [ERROR]  Exception occurred while handling uri: 'http://localhost:5005/socket.io/?EIO=3&transport=polling&t=MlasFIF'
Traceback (most recent call last):
  File "c:\users\prashant.kamble\appdata\local\programs\python\python36\lib\site-packages\sanic\app.py", line 893, in handle_request
    handler, args, kwargs, uri = self.router.get(request)
  File "c:\users\prashant.kamble\appdata\local\programs\python\python36\lib\site-packages\sanic\router.py", line 407, in get
    return self._get(request.path, request.method, "")
  File "c:\users\prashant.kamble\appdata\local\programs\python\python36\lib\site-packages\sanic\router.py", line 469, in _get
    raise NotFound("Requested URL {} not found".format(url))
sanic.exceptions.NotFound: Requested URL /socket.io/ not found
2019-07-12 11:53:12,390 [ERROR]  Exception occurred while handling uri: 'http://localhost:5005/socket.io/?EIO=3&transport=polling&t=MlasLeT'
Traceback (most recent call last):
  File "c:\users\prashant.kamble\appdata\local\programs\python\python36\lib\site-packages\sanic\app.py", line 893, in handle_request
    handler, args, kwargs, uri = self.router.get(request)
  File "c:\users\prashant.kamble\appdata\local\programs\python\python36\lib\site-packages\sanic\router.py", line 407, in get
    return self._get(request.path, request.method, "")
  File "c:\users\prashant.kamble\appdata\local\programs\python\python36\lib\site-packages\sanic\router.py", line 469, in _get
    raise NotFound("Requested URL {} not found".format(url))
sanic.exceptions.NotFound: Requested URL /socket.io/ not found
2019-07-12 11:53:19,387 [ERROR]  Exception occurred while handling uri: 'http://localhost:5005/socket.io/?EIO=3&transport=polling&t=MlasQmZ'
Traceback (most recent call last):
  File "c:\users\prashant.kamble\appdata\local\programs\python\python36\lib\site-packages\sanic\app.py", line 893, in handle_request
    handler, args, kwargs, uri = self.router.get(request)
  File "c:\users\prashant.kamble\appdata\local\programs\python\python36\lib\site-packages\sanic\router.py", line 407, in get
    return self._get(request.path, request.method, "")
  File "c:\users\prashant.kamble\appdata\local\programs\python\python36\lib\site-packages\sanic\router.py", line 469, in _get
    raise NotFound("Requested URL {} not found".format(url))
sanic.exceptions.NotFound: Requested URL /socket.io/ not found
2019-07-12 11:53:26,193 [ERROR]  Exception occurred while handling uri: 'http://localhost:5005/socket.io/?EIO=3&transport=polling&t=MlasSEK'
Traceback (most recent call last):
  File "c:\users\prashant.kamble\appdata\local\programs\python\python36\lib\site-packages\sanic\app.py", line 893, in handle_request
    handler, args, kwargs, uri = self.router.get(request)
  File "c:\users\prashant.kamble\appdata\local\programs\python\python36\lib\site-packages\sanic\router.py", line 407, in get
    return self._get(request.path, request.method, "")
  File "c:\users\prashant.kamble\appdata\local\programs\python\python36\lib\site-packages\sanic\router.py", line 469, in _get
    raise NotFound("Requested URL {} not found".format(url))
sanic.exceptions.NotFound: Requested URL /socket.io/ not found
2019-07-12 11:53:32,387 [ERROR]  Exception occurred while handling uri: 'http://localhost:5005/socket.io/?EIO=3&transport=polling&t=MlasTxi'
Traceback (most recent call last):
  File "c:\users\prashant.kamble\appdata\local\programs\python\python36\lib\site-packages\sanic\app.py", line 893, in handle_request
    handler, args, kwargs, uri = self.router.get(request)
  File "c:\users\prashant.kamble\appdata\local\programs\python\python36\lib\site-packages\sanic\router.py", line 407, in get
    return self._get(request.path, request.method, "")
  File "c:\users\prashant.kamble\appdata\local\programs\python\python36\lib\site-packages\sanic\router.py", line 469, in _get
    raise NotFound("Requested URL {} not found".format(url))
sanic.exceptions.NotFound: Requested URL /socket.io/ not found
2019-07-12 11:54:46,209 [ERROR]  Exception occurred while handling uri: unknown
NoneType: None
2019-07-12 11:54:46,210 [ERROR]  Exception occurred while handling uri: 'http://localhost:5005/socket.io/?EIO=3&transport=polling&t=MlasVPT'
Traceback (most recent call last):
  File "c:\users\prashant.kamble\appdata\local\programs\python\python36\lib\site-packages\sanic\app.py", line 893, in handle_request
    handler, args, kwargs, uri = self.router.get(request)
  File "c:\users\prashant.kamble\appdata\local\programs\python\python36\lib\site-packages\sanic\router.py", line 407, in get
    return self._get(request.path, request.method, "")
  File "c:\users\prashant.kamble\appdata\local\programs\python\python36\lib\site-packages\sanic\router.py", line 469, in _get
    raise NotFound("Requested URL {} not found".format(url))
sanic.exceptions.NotFound: Requested URL /socket.io/ not found
2019-07-12 11:54:46,212 [ERROR]  Exception occurred while handling uri: 'http://localhost:5005/socket.io/?EIO=3&transport=polling&t=Mlasi5-'
Traceback (most recent call last):
  File "c:\users\prashant.kamble\appdata\local\programs\python\python36\lib\site-packages\sanic\app.py", line 893, in handle_request
    handler, args, kwargs, uri = self.router.get(request)
  File "c:\users\prashant.kamble\appdata\local\programs\python\python36\lib\site-packages\sanic\router.py", line 407, in get
    return self._get(request.path, request.method, "")
  File "c:\users\prashant.kamble\appdata\local\programs\python\python36\lib\site-packages\sanic\router.py", line 469, in _get
    raise NotFound("Requested URL {} not found".format(url))
sanic.exceptions.NotFound: Requested URL /socket.io/ not found
2019-07-12 11:54:46,214 [ERROR]  Exception occurred while handling uri: 'http://localhost:5005/socket.io/?EIO=3&transport=polling&t=Mlasblj'
Traceback (most recent call last):
  File "c:\users\prashant.kamble\appdata\local\programs\python\python36\lib\site-packages\sanic\app.py", line 893, in handle_request
    handler, args, kwargs, uri = self.router.get(request)
  File "c:\users\prashant.kamble\appdata\local\programs\python\python36\lib\site-packages\sanic\router.py", line 407, in get
    return self._get(request.path, request.method, "")
  File "c:\users\prashant.kamble\appdata\local\programs\python\python36\lib\site-packages\sanic\router.py", line 469, in _get
    raise NotFound("Requested URL {} not found".format(url))
sanic.exceptions.NotFound: Requested URL /socket.io/ not found
2019-07-12 11:54:55,940 [ERROR]  Exception occurred while handling uri: 'http://localhost:5005/socket.io/?EIO=3&transport=polling&t=MlasnTl'
Traceback (most recent call last):
  File "c:\users\prashant.kamble\appdata\local\programs\python\python36\lib\site-packages\sanic\app.py", line 893, in handle_request
    handler, args, kwargs, uri = self.router.get(request)
  File "c:\users\prashant.kamble\appdata\local\programs\python\python36\lib\site-packages\sanic\router.py", line 407, in get
    return self._get(request.path, request.method, "")
  File "c:\users\prashant.kamble\appdata\local\programs\python\python36\lib\site-packages\sanic\router.py", line 469, in _get
    raise NotFound("Requested URL {} not found".format(url))
sanic.exceptions.NotFound: Requested URL /socket.io/ not found
2019-07-12 12:10:24,646 [ERROR]  Exception occurred while handling uri: unknown
NoneType: None
2019-07-12 13:30:35,294 [ERROR]  Exception occurred while handling uri: 'http://localhost:5005/socket.io/?EIO=3&transport=polling&t=MlbBqeW'
Traceback (most recent call last):
  File "c:\users\prashant.kamble\appdata\local\programs\python\python36\lib\site-packages\sanic\app.py", line 893, in handle_request
    handler, args, kwargs, uri = self.router.get(request)
  File "c:\users\prashant.kamble\appdata\local\programs\python\python36\lib\site-packages\sanic\router.py", line 407, in get
    return self._get(request.path, request.method, "")
  File "c:\users\prashant.kamble\appdata\local\programs\python\python36\lib\site-packages\sanic\router.py", line 469, in _get
    raise NotFound("Requested URL {} not found".format(url))
sanic.exceptions.NotFound: Requested URL /socket.io/ not found
2019-07-12 13:30:35,297 [ERROR]  Exception occurred while handling uri: 'http://localhost:5005/socket.io/?EIO=3&transport=polling&t=MlbBkIE'
Traceback (most recent call last):
  File "c:\users\prashant.kamble\appdata\local\programs\python\python36\lib\site-packages\sanic\app.py", line 893, in handle_request
    handler, args, kwargs, uri = self.router.get(request)
  File "c:\users\prashant.kamble\appdata\local\programs\python\python36\lib\site-packages\sanic\router.py", line 407, in get
    return self._get(request.path, request.method, "")
  File "c:\users\prashant.kamble\appdata\local\programs\python\python36\lib\site-packages\sanic\router.py", line 469, in _get
    raise NotFound("Requested URL {} not found".format(url))
sanic.exceptions.NotFound: Requested URL /socket.io/ not found
2019-07-12 13:30:35,299 [ERROR]  Exception occurred while handling uri: 'http://localhost:5005/socket.io/?EIO=3&transport=polling&t=MlbC7hC'
Traceback (most recent call last):
  File "c:\users\prashant.kamble\appdata\local\programs\python\python36\lib\site-packages\sanic\app.py", line 893, in handle_request
    handler, args, kwargs, uri = self.router.get(request)
  File "c:\users\prashant.kamble\appdata\local\programs\python\python36\lib\site-packages\sanic\router.py", line 407, in get
    return self._get(request.path, request.method, "")
  File "c:\users\prashant.kamble\appdata\local\programs\python\python36\lib\site-packages\sanic\router.py", line 469, in _get
    raise NotFound("Requested URL {} not found".format(url))
sanic.exceptions.NotFound: Requested URL /socket.io/ not found
2019-07-12 13:30:35,301 [ERROR]  Exception occurred while handling uri: 'http://localhost:5005/socket.io/?EIO=3&transport=polling&t=MlbBw-l'
Traceback (most recent call last):
  File "c:\users\prashant.kamble\appdata\local\programs\python\python36\lib\site-packages\sanic\app.py", line 893, in handle_request
    handler, args, kwargs, uri = self.router.get(request)
  File "c:\users\prashant.kamble\appdata\local\programs\python\python36\lib\site-packages\sanic\router.py", line 407, in get
    return self._get(request.path, request.method, "")
  File "c:\users\prashant.kamble\appdata\local\programs\python\python36\lib\site-packages\sanic\router.py", line 469, in _get
    raise NotFound("Requested URL {} not found".format(url))
sanic.exceptions.NotFound: Requested URL /socket.io/ not found
2019-07-12 13:30:35,303 [ERROR]  Exception occurred while handling uri: 'http://localhost:5005/socket.io/?EIO=3&transport=polling&t=MlbC1K_'
Traceback (most recent call last):
  File "c:\users\prashant.kamble\appdata\local\programs\python\python36\lib\site-packages\sanic\app.py", line 893, in handle_request
    handler, args, kwargs, uri = self.router.get(request)
  File "c:\users\prashant.kamble\appdata\local\programs\python\python36\lib\site-packages\sanic\router.py", line 407, in get
    return self._get(request.path, request.method, "")
  File "c:\users\prashant.kamble\appdata\local\programs\python\python36\lib\site-packages\sanic\router.py", line 469, in _get
    raise NotFound("Requested URL {} not found".format(url))
sanic.exceptions.NotFound: Requested URL /socket.io/ not found
2019-07-12 13:30:35,312 [ERROR]  Exception occurred while handling uri: 'http://localhost:5005/socket.io/?EIO=3&transport=polling&t=MlbCDnu'
Traceback (most recent call last):
  File "c:\users\prashant.kamble\appdata\local\programs\python\python36\lib\site-packages\sanic\app.py", line 893, in handle_request
    handler, args, kwargs, uri = self.router.get(request)
  File "c:\users\prashant.kamble\appdata\local\programs\python\python36\lib\site-packages\sanic\router.py", line 407, in get
    return self._get(request.path, request.method, "")
  File "c:\users\prashant.kamble\appdata\local\programs\python\python36\lib\site-packages\sanic\router.py", line 469, in _get
    raise NotFound("Requested URL {} not found".format(url))
sanic.exceptions.NotFound: Requested URL /socket.io/ not found
2019-07-12 13:30:35,316 [ERROR]  Exception occurred while handling uri: 'http://localhost:5005/socket.io/?EIO=3&transport=polling&t=MlbCdAu'
Traceback (most recent call last):
  File "c:\users\prashant.kamble\appdata\local\programs\python\python36\lib\site-packages\sanic\app.py", line 893, in handle_request
    handler, args, kwargs, uri = self.router.get(request)
  File "c:\users\prashant.kamble\appdata\local\programs\python\python36\lib\site-packages\sanic\router.py", line 407, in get
    return self._get(request.path, request.method, "")
  File "c:\users\prashant.kamble\appdata\local\programs\python\python36\lib\site-packages\sanic\router.py", line 469, in _get
    raise NotFound("Requested URL {} not found".format(url))
sanic.exceptions.NotFound: Requested URL /socket.io/ not found
2019-07-12 13:30:35,319 [ERROR]  Exception occurred while handling uri: 'http://localhost:5005/socket.io/?EIO=3&transport=polling&t=MlbCK85'
Traceback (most recent call last):
  File "c:\users\prashant.kamble\appdata\local\programs\python\python36\lib\site-packages\sanic\app.py", line 893, in handle_request
    handler, args, kwargs, uri = self.router.get(request)
  File "c:\users\prashant.kamble\appdata\local\programs\python\python36\lib\site-packages\sanic\router.py", line 407, in get
    return self._get(request.path, request.method, "")
  File "c:\users\prashant.kamble\appdata\local\programs\python\python36\lib\site-packages\sanic\router.py", line 469, in _get
    raise NotFound("Requested URL {} not found".format(url))
sanic.exceptions.NotFound: Requested URL /socket.io/ not found
2019-07-12 13:30:35,321 [ERROR]  Exception occurred while handling uri: 'http://localhost:5005/socket.io/?EIO=3&transport=polling&t=MlbCQUN'
Traceback (most recent call last):
  File "c:\users\prashant.kamble\appdata\local\programs\python\python36\lib\site-packages\sanic\app.py", line 893, in handle_request
    handler, args, kwargs, uri = self.router.get(request)
  File "c:\users\prashant.kamble\appdata\local\programs\python\python36\lib\site-packages\sanic\router.py", line 407, in get
    return self._get(request.path, request.method, "")
  File "c:\users\prashant.kamble\appdata\local\programs\python\python36\lib\site-packages\sanic\router.py", line 469, in _get
    raise NotFound("Requested URL {} not found".format(url))
sanic.exceptions.NotFound: Requested URL /socket.io/ not found
2019-07-12 13:30:35,323 [ERROR]  Exception occurred while handling uri: 'http://localhost:5005/socket.io/?EIO=3&transport=polling&t=MlbCWqb'
Traceback (most recent call last):
  File "c:\users\prashant.kamble\appdata\local\programs\python\python36\lib\site-packages\sanic\app.py", line 893, in handle_request
    handler, args, kwargs, uri = self.router.get(request)
  File "c:\users\prashant.kamble\appdata\local\programs\python\python36\lib\site-packages\sanic\router.py", line 407, in get
    return self._get(request.path, request.method, "")
  File "c:\users\prashant.kamble\appdata\local\programs\python\python36\lib\site-packages\sanic\router.py", line 469, in _get
    raise NotFound("Requested URL {} not found".format(url))
sanic.exceptions.NotFound: Requested URL /socket.io/ not found
2019-07-12 13:32:16,643 [ERROR]  Exception occurred while handling uri: 'http://localhost:5005/socket.io/?EIO=3&transport=polling&t=MlbCj1u'
Traceback (most recent call last):
  File "c:\users\prashant.kamble\appdata\local\programs\python\python36\lib\site-packages\sanic\app.py", line 893, in handle_request
    handler, args, kwargs, uri = self.router.get(request)
  File "c:\users\prashant.kamble\appdata\local\programs\python\python36\lib\site-packages\sanic\router.py", line 407, in get
    return self._get(request.path, request.method, "")
  File "c:\users\prashant.kamble\appdata\local\programs\python\python36\lib\site-packages\sanic\router.py", line 469, in _get
    raise NotFound("Requested URL {} not found".format(url))
sanic.exceptions.NotFound: Requested URL /socket.io/ not found
2019-07-12 13:32:16,645 [ERROR]  Exception occurred while handling uri: 'http://localhost:5005/socket.io/?EIO=3&transport=polling&t=MlbD04e'
Traceback (most recent call last):
  File "c:\users\prashant.kamble\appdata\local\programs\python\python36\lib\site-packages\sanic\app.py", line 893, in handle_request
    handler, args, kwargs, uri = self.router.get(request)
  File "c:\users\prashant.kamble\appdata\local\programs\python\python36\lib\site-packages\sanic\router.py", line 407, in get
    return self._get(request.path, request.method, "")
  File "c:\users\prashant.kamble\appdata\local\programs\python\python36\lib\site-packages\sanic\router.py", line 469, in _get
    raise NotFound("Requested URL {} not found".format(url))
sanic.exceptions.NotFound: Requested URL /socket.io/ not found
2019-07-12 13:32:16,647 [ERROR]  Exception occurred while handling uri: 'http://localhost:5005/socket.io/?EIO=3&transport=polling&t=MlbCvkN'
Traceback (most recent call last):
  File "c:\users\prashant.kamble\appdata\local\programs\python\python36\lib\site-packages\sanic\app.py", line 893, in handle_request
    handler, args, kwargs, uri = self.router.get(request)
  File "c:\users\prashant.kamble\appdata\local\programs\python\python36\lib\site-packages\sanic\router.py", line 407, in get
    return self._get(request.path, request.method, "")
  File "c:\users\prashant.kamble\appdata\local\programs\python\python36\lib\site-packages\sanic\router.py", line 469, in _get
    raise NotFound("Requested URL {} not found".format(url))
sanic.exceptions.NotFound: Requested URL /socket.io/ not found
2019-07-12 13:32:16,649 [ERROR]  Exception occurred while handling uri: 'http://localhost:5005/socket.io/?EIO=3&transport=polling&t=MlbCpO6'
Traceback (most recent call last):
  File "c:\users\prashant.kamble\appdata\local\programs\python\python36\lib\site-packages\sanic\app.py", line 893, in handle_request
    handler, args, kwargs, uri = self.router.get(request)
  File "c:\users\prashant.kamble\appdata\local\programs\python\python36\lib\site-packages\sanic\router.py", line 407, in get
    return self._get(request.path, request.method, "")
  File "c:\users\prashant.kamble\appdata\local\programs\python\python36\lib\site-packages\sanic\router.py", line 469, in _get
    raise NotFound("Requested URL {} not found".format(url))
sanic.exceptions.NotFound: Requested URL /socket.io/ not found
2019-07-12 13:32:22,389 [ERROR]  Exception occurred while handling uri: 'http://localhost:5005/socket.io/?EIO=3&transport=polling&t=MlbD5hz'
Traceback (most recent call last):
  File "c:\users\prashant.kamble\appdata\local\programs\python\python36\lib\site-packages\sanic\app.py", line 893, in handle_request
    handler, args, kwargs, uri = self.router.get(request)
  File "c:\users\prashant.kamble\appdata\local\programs\python\python36\lib\site-packages\sanic\router.py", line 407, in get
    return self._get(request.path, request.method, "")
  File "c:\users\prashant.kamble\appdata\local\programs\python\python36\lib\site-packages\sanic\router.py", line 469, in _get
    raise NotFound("Requested URL {} not found".format(url))
sanic.exceptions.NotFound: Requested URL /socket.io/ not found
2019-07-12 13:32:29,762 [ERROR]  Exception occurred while handling uri: 'http://localhost:5005/socket.io/?EIO=3&transport=polling&t=MlbD79l'
Traceback (most recent call last):
  File "c:\users\prashant.kamble\appdata\local\programs\python\python36\lib\site-packages\sanic\app.py", line 893, in handle_request
    handler, args, kwargs, uri = self.router.get(request)
  File "c:\users\prashant.kamble\appdata\local\programs\python\python36\lib\site-packages\sanic\router.py", line 407, in get
    return self._get(request.path, request.method, "")
  File "c:\users\prashant.kamble\appdata\local\programs\python\python36\lib\site-packages\sanic\router.py", line 469, in _get
    raise NotFound("Requested URL {} not found".format(url))
sanic.exceptions.NotFound: Requested URL /socket.io/ not found
2019-07-12 13:33:00,790 [ERROR]  Exception occurred while handling uri: 'http://localhost:5005/socket.io/?EIO=3&transport=polling&t=MlbD8t5'
Traceback (most recent call last):
  File "c:\users\prashant.kamble\appdata\local\programs\python\python36\lib\site-packages\sanic\app.py", line 893, in handle_request
    handler, args, kwargs, uri = self.router.get(request)
  File "c:\users\prashant.kamble\appdata\local\programs\python\python36\lib\site-packages\sanic\router.py", line 407, in get
    return self._get(request.path, request.method, "")
  File "c:\users\prashant.kamble\appdata\local\programs\python\python36\lib\site-packages\sanic\router.py", line 469, in _get
    raise NotFound("Requested URL {} not found".format(url))
sanic.exceptions.NotFound: Requested URL /socket.io/ not found
2019-07-12 13:33:01,085 [ERROR]  Exception occurred while handling uri: 'http://localhost:5005/socket.io/?EIO=3&transport=polling&t=MlbDFDM'
Traceback (most recent call last):
  File "c:\users\prashant.kamble\appdata\local\programs\python\python36\lib\site-packages\sanic\app.py", line 893, in handle_request
    handler, args, kwargs, uri = self.router.get(request)
  File "c:\users\prashant.kamble\appdata\local\programs\python\python36\lib\site-packages\sanic\router.py", line 407, in get
    return self._get(request.path, request.method, "")
  File "c:\users\prashant.kamble\appdata\local\programs\python\python36\lib\site-packages\sanic\router.py", line 469, in _get
    raise NotFound("Requested URL {} not found".format(url))
sanic.exceptions.NotFound: Requested URL /socket.io/ not found
2019-07-12 13:33:28,837 [ERROR]  Exception occurred while handling uri: 'http://localhost:5005/socket.io/?EIO=3&transport=polling&t=MlbDGh6'
Traceback (most recent call last):
  File "c:\users\prashant.kamble\appdata\local\programs\python\python36\lib\site-packages\sanic\app.py", line 893, in handle_request
    handler, args, kwargs, uri = self.router.get(request)
  File "c:\users\prashant.kamble\appdata\local\programs\python\python36\lib\site-packages\sanic\router.py", line 407, in get
    return self._get(request.path, request.method, "")
  File "c:\users\prashant.kamble\appdata\local\programs\python\python36\lib\site-packages\sanic\router.py", line 469, in _get
    raise NotFound("Requested URL {} not found".format(url))
sanic.exceptions.NotFound: Requested URL /socket.io/ not found
2019-07-12 13:35:12,880 [ERROR]  Exception occurred while handling uri: 'http://localhost:5005/socket.io/?EIO=3&transport=polling&t=MlbDilz'
Traceback (most recent call last):
  File "c:\users\prashant.kamble\appdata\local\programs\python\python36\lib\site-packages\sanic\app.py", line 893, in handle_request
    handler, args, kwargs, uri = self.router.get(request)
  File "c:\users\prashant.kamble\appdata\local\programs\python\python36\lib\site-packages\sanic\router.py", line 407, in get
    return self._get(request.path, request.method, "")
  File "c:\users\prashant.kamble\appdata\local\programs\python\python36\lib\site-packages\sanic\router.py", line 469, in _get
    raise NotFound("Requested URL {} not found".format(url))
sanic.exceptions.NotFound: Requested URL /socket.io/ not found
2019-07-12 13:35:51,096 [ERROR]  Exception occurred while handling uri: 'http://localhost:5005/socket.io/?EIO=3&transport=polling&t=MlbDmfz'
Traceback (most recent call last):
  File "c:\users\prashant.kamble\appdata\local\programs\python\python36\lib\site-packages\sanic\app.py", line 893, in handle_request
    handler, args, kwargs, uri = self.router.get(request)
  File "c:\users\prashant.kamble\appdata\local\programs\python\python36\lib\site-packages\sanic\router.py", line 407, in get
    return self._get(request.path, request.method, "")
  File "c:\users\prashant.kamble\appdata\local\programs\python\python36\lib\site-packages\sanic\router.py", line 469, in _get
    raise NotFound("Requested URL {} not found".format(url))
sanic.exceptions.NotFound: Requested URL /socket.io/ not found
2019-07-12 13:37:30,349 [ERROR]  Exception occurred while handling uri: 'http://localhost:5005/socket.io/?EIO=3&transport=polling&t=MlbECFa'
Traceback (most recent call last):
  File "c:\users\prashant.kamble\appdata\local\programs\python\python36\lib\site-packages\sanic\app.py", line 893, in handle_request
    handler, args, kwargs, uri = self.router.get(request)
  File "c:\users\prashant.kamble\appdata\local\programs\python\python36\lib\site-packages\sanic\router.py", line 407, in get
    return self._get(request.path, request.method, "")
  File "c:\users\prashant.kamble\appdata\local\programs\python\python36\lib\site-packages\sanic\router.py", line 469, in _get
    raise NotFound("Requested URL {} not found".format(url))
sanic.exceptions.NotFound: Requested URL /socket.io/ not found
2019-07-12 13:37:40,856 [ERROR]  Exception occurred while handling uri: 'http://localhost:5005/socket.io/?EIO=3&transport=polling&t=MlbEIME'
Traceback (most recent call last):
  File "c:\users\prashant.kamble\appdata\local\programs\python\python36\lib\site-packages\sanic\app.py", line 893, in handle_request
    handler, args, kwargs, uri = self.router.get(request)
  File "c:\users\prashant.kamble\appdata\local\programs\python\python36\lib\site-packages\sanic\router.py", line 407, in get
    return self._get(request.path, request.method, "")
  File "c:\users\prashant.kamble\appdata\local\programs\python\python36\lib\site-packages\sanic\router.py", line 469, in _get
    raise NotFound("Requested URL {} not found".format(url))
sanic.exceptions.NotFound: Requested URL /socket.io/ not found
2019-07-12 13:37:54,408 [ERROR]  Exception occurred while handling uri: 'http://localhost:5005/socket.io/?EIO=3&transport=polling&t=MlbEL24'
Traceback (most recent call last):
  File "c:\users\prashant.kamble\appdata\local\programs\python\python36\lib\site-packages\sanic\app.py", line 893, in handle_request
    handler, args, kwargs, uri = self.router.get(request)
  File "c:\users\prashant.kamble\appdata\local\programs\python\python36\lib\site-packages\sanic\router.py", line 407, in get
    return self._get(request.path, request.method, "")
  File "c:\users\prashant.kamble\appdata\local\programs\python\python36\lib\site-packages\sanic\router.py", line 469, in _get
    raise NotFound("Requested URL {} not found".format(url))
sanic.exceptions.NotFound: Requested URL /socket.io/ not found
2019-07-12 13:38:00,390 [ERROR]  Exception occurred while handling uri: 'http://localhost:5005/socket.io/?EIO=3&transport=polling&t=MlbEODE'
Traceback (most recent call last):
  File "c:\users\prashant.kamble\appdata\local\programs\python\python36\lib\site-packages\sanic\app.py", line 893, in handle_request
    handler, args, kwargs, uri = self.router.get(request)
  File "c:\users\prashant.kamble\appdata\local\programs\python\python36\lib\site-packages\sanic\router.py", line 407, in get
    return self._get(request.path, request.method, "")
  File "c:\users\prashant.kamble\appdata\local\programs\python\python36\lib\site-packages\sanic\router.py", line 469, in _get
    raise NotFound("Requested URL {} not found".format(url))
sanic.exceptions.NotFound: Requested URL /socket.io/ not found
2019-07-12 13:38:08,579 [ERROR]  Exception occurred while handling uri: 'http://localhost:5005/socket.io/?EIO=3&transport=polling&t=MlbEPg-'
Traceback (most recent call last):
  File "c:\users\prashant.kamble\appdata\local\programs\python\python36\lib\site-packages\sanic\app.py", line 893, in handle_request
    handler, args, kwargs, uri = self.router.get(request)
  File "c:\users\prashant.kamble\appdata\local\programs\python\python36\lib\site-packages\sanic\router.py", line 407, in get
    return self._get(request.path, request.method, "")
  File "c:\users\prashant.kamble\appdata\local\programs\python\python36\lib\site-packages\sanic\router.py", line 469, in _get
    raise NotFound("Requested URL {} not found".format(url))
sanic.exceptions.NotFound: Requested URL /socket.io/ not found
2019-07-12 13:38:15,408 [ERROR]  Exception occurred while handling uri: 'http://localhost:5005/socket.io/?EIO=3&transport=polling&t=MlbERtZ'
Traceback (most recent call last):
  File "c:\users\prashant.kamble\appdata\local\programs\python\python36\lib\site-packages\sanic\app.py", line 893, in handle_request
    handler, args, kwargs, uri = self.router.get(request)
  File "c:\users\prashant.kamble\appdata\local\programs\python\python36\lib\site-packages\sanic\router.py", line 407, in get
    return self._get(request.path, request.method, "")
  File "c:\users\prashant.kamble\appdata\local\programs\python\python36\lib\site-packages\sanic\router.py", line 469, in _get
    raise NotFound("Requested URL {} not found".format(url))
sanic.exceptions.NotFound: Requested URL /socket.io/ not found
2019-07-12 13:51:01,035 [ERROR]  Exception occurred while handling uri: unknown
NoneType: None
2019-07-12 13:51:01,036 [ERROR]  Exception occurred while handling uri: 'http://localhost:5005/socket.io/?EIO=3&transport=polling&t=MlbETLV'
Traceback (most recent call last):
  File "c:\users\prashant.kamble\appdata\local\programs\python\python36\lib\site-packages\sanic\app.py", line 893, in handle_request
    handler, args, kwargs, uri = self.router.get(request)
  File "c:\users\prashant.kamble\appdata\local\programs\python\python36\lib\site-packages\sanic\router.py", line 407, in get
    return self._get(request.path, request.method, "")
  File "c:\users\prashant.kamble\appdata\local\programs\python\python36\lib\site-packages\sanic\router.py", line 469, in _get
    raise NotFound("Requested URL {} not found".format(url))
sanic.exceptions.NotFound: Requested URL /socket.io/ not found
2019-07-12 13:52:10,391 [ERROR]  Exception occurred while handling uri: 'http://localhost:5005/socket.io/?EIO=3&transport=polling&t=MlbHdkS'
Traceback (most recent call last):
  File "c:\users\prashant.kamble\appdata\local\programs\python\python36\lib\site-packages\sanic\app.py", line 893, in handle_request
    handler, args, kwargs, uri = self.router.get(request)
  File "c:\users\prashant.kamble\appdata\local\programs\python\python36\lib\site-packages\sanic\router.py", line 407, in get
    return self._get(request.path, request.method, "")
  File "c:\users\prashant.kamble\appdata\local\programs\python\python36\lib\site-packages\sanic\router.py", line 469, in _get
    raise NotFound("Requested URL {} not found".format(url))
sanic.exceptions.NotFound: Requested URL /socket.io/ not found
2019-07-12 13:52:24,635 [ERROR]  Exception occurred while handling uri: 'http://localhost:5005/socket.io/?EIO=3&transport=polling&t=MlbHfCE'
Traceback (most recent call last):
  File "c:\users\prashant.kamble\appdata\local\programs\python\python36\lib\site-packages\sanic\app.py", line 893, in handle_request
    handler, args, kwargs, uri = self.router.get(request)
  File "c:\users\prashant.kamble\appdata\local\programs\python\python36\lib\site-packages\sanic\router.py", line 407, in get
    return self._get(request.path, request.method, "")
  File "c:\users\prashant.kamble\appdata\local\programs\python\python36\lib\site-packages\sanic\router.py", line 469, in _get
    raise NotFound("Requested URL {} not found".format(url))
sanic.exceptions.NotFound: Requested URL /socket.io/ not found
2019-07-12 13:53:10,057 [ERROR]  Exception occurred while handling uri: 'http://localhost:5005/socket.io/?EIO=3&transport=polling&t=MlbHicy'
Traceback (most recent call last):
  File "c:\users\prashant.kamble\appdata\local\programs\python\python36\lib\site-packages\sanic\app.py", line 893, in handle_request
    handler, args, kwargs, uri = self.router.get(request)
  File "c:\users\prashant.kamble\appdata\local\programs\python\python36\lib\site-packages\sanic\router.py", line 407, in get
    return self._get(request.path, request.method, "")
  File "c:\users\prashant.kamble\appdata\local\programs\python\python36\lib\site-packages\sanic\router.py", line 469, in _get
    raise NotFound("Requested URL {} not found".format(url))
sanic.exceptions.NotFound: Requested URL /socket.io/ not found
2019-07-12 13:53:10,059 [ERROR]  Exception occurred while handling uri: 'http://localhost:5005/socket.io/?EIO=3&transport=polling&t=MlbHozF'
Traceback (most recent call last):
  File "c:\users\prashant.kamble\appdata\local\programs\python\python36\lib\site-packages\sanic\app.py", line 893, in handle_request
    handler, args, kwargs, uri = self.router.get(request)
  File "c:\users\prashant.kamble\appdata\local\programs\python\python36\lib\site-packages\sanic\router.py", line 407, in get
    return self._get(request.path, request.method, "")
  File "c:\users\prashant.kamble\appdata\local\programs\python\python36\lib\site-packages\sanic\router.py", line 469, in _get
    raise NotFound("Requested URL {} not found".format(url))
sanic.exceptions.NotFound: Requested URL /socket.io/ not found
2019-07-12 13:53:21,553 [ERROR]  Exception occurred while handling uri: 'http://localhost:5005/socket.io/?EIO=3&transport=polling&t=MlbHtc6'
Traceback (most recent call last):
  File "c:\users\prashant.kamble\appdata\local\programs\python\python36\lib\site-packages\sanic\app.py", line 893, in handle_request
    handler, args, kwargs, uri = self.router.get(request)
  File "c:\users\prashant.kamble\appdata\local\programs\python\python36\lib\site-packages\sanic\router.py", line 407, in get
    return self._get(request.path, request.method, "")
  File "c:\users\prashant.kamble\appdata\local\programs\python\python36\lib\site-packages\sanic\router.py", line 469, in _get
    raise NotFound("Requested URL {} not found".format(url))
sanic.exceptions.NotFound: Requested URL /socket.io/ not found
2019-07-12 13:53:33,622 [ERROR]  Exception occurred while handling uri: 'http://localhost:5005/socket.io/?EIO=3&transport=polling&t=MlbHwXb'
Traceback (most recent call last):
  File "c:\users\prashant.kamble\appdata\local\programs\python\python36\lib\site-packages\sanic\app.py", line 893, in handle_request
    handler, args, kwargs, uri = self.router.get(request)
  File "c:\users\prashant.kamble\appdata\local\programs\python\python36\lib\site-packages\sanic\router.py", line 407, in get
    return self._get(request.path, request.method, "")
  File "c:\users\prashant.kamble\appdata\local\programs\python\python36\lib\site-packages\sanic\router.py", line 469, in _get
    raise NotFound("Requested URL {} not found".format(url))
sanic.exceptions.NotFound: Requested URL /socket.io/ not found
2019-07-12 14:03:55,803 [ERROR]  Exception occurred while handling uri: 'http://localhost:5005/socket.io/?EIO=3&transport=polling&t=MlbKJcV'
Traceback (most recent call last):
  File "c:\users\prashant.kamble\appdata\local\programs\python\python36\lib\site-packages\sanic\app.py", line 893, in handle_request
    handler, args, kwargs, uri = self.router.get(request)
  File "c:\users\prashant.kamble\appdata\local\programs\python\python36\lib\site-packages\sanic\router.py", line 407, in get
    return self._get(request.path, request.method, "")
  File "c:\users\prashant.kamble\appdata\local\programs\python\python36\lib\site-packages\sanic\router.py", line 469, in _get
    raise NotFound("Requested URL {} not found".format(url))
sanic.exceptions.NotFound: Requested URL /socket.io/ not found
2019-08-16 16:57:01,172 [DEBUG]  Available web server routes: 
/webhooks/rest                                     GET                            custom_webhook_CmdlineInput.health
/webhooks/rest/webhook                             POST                           custom_webhook_CmdlineInput.receive
2019-08-19 17:57:33,942 [ERROR]  Unable to start server
Traceback (most recent call last):
  File "c:\users\prashant.kamble\appdata\local\programs\python\python36\lib\site-packages\sanic\server.py", line 745, in serve
    http_server = loop.run_until_complete(server_coroutine)
  File "C:\Users\Prashant.Kamble\AppData\Local\Programs\Python\Python36\Lib\asyncio\base_events.py", line 482, in run_until_complete
    raise RuntimeError('Event loop stopped before Future completed.')
RuntimeError: Event loop stopped before Future completed.
